[2024-07-01T23:07:10.812+0000] {processor.py:161} INFO - Started process (PID=2305) to work on /opt/airflow/dags/mydag.py
[2024-07-01T23:07:10.814+0000] {processor.py:830} INFO - Processing file /opt/airflow/dags/mydag.py for tasks to queue
[2024-07-01T23:07:10.816+0000] {logging_mixin.py:188} INFO - [2024-07-01T23:07:10.815+0000] {dagbag.py:538} INFO - Filling up the DagBag from /opt/airflow/dags/mydag.py
[2024-07-01T23:07:10.863+0000] {logging_mixin.py:188} INFO - [2024-07-01T23:07:10.852+0000] {dagbag.py:348} ERROR - Failed to import: /opt/airflow/dags/mydag.py
Traceback (most recent call last):
  File "/home/airflow/.local/lib/python3.8/site-packages/airflow/models/dagbag.py", line 344, in parse
    loader.exec_module(new_module)
  File "<frozen importlib._bootstrap_external>", line 843, in exec_module
  File "<frozen importlib._bootstrap>", line 219, in _call_with_frames_removed
  File "/opt/airflow/dags/mydag.py", line 18, in <module>
    dag = DAG(
  File "/home/airflow/.local/lib/python3.8/site-packages/airflow/models/dag.py", line 498, in __init__
    validate_key(dag_id)
  File "/home/airflow/.local/lib/python3.8/site-packages/airflow/utils/helpers.py", line 57, in validate_key
    raise AirflowException(
airflow.exceptions.AirflowException: The key 'bitcoin data fetching' has to be made of alphanumeric characters, dashes, dots and underscores exclusively
[2024-07-01T23:07:10.865+0000] {processor.py:842} WARNING - No viable dags retrieved from /opt/airflow/dags/mydag.py
[2024-07-01T23:07:10.902+0000] {processor.py:183} INFO - Processing /opt/airflow/dags/mydag.py took 0.096 seconds
[2024-07-01T23:07:41.112+0000] {processor.py:161} INFO - Started process (PID=2312) to work on /opt/airflow/dags/mydag.py
[2024-07-01T23:07:41.114+0000] {processor.py:830} INFO - Processing file /opt/airflow/dags/mydag.py for tasks to queue
[2024-07-01T23:07:41.116+0000] {logging_mixin.py:188} INFO - [2024-07-01T23:07:41.115+0000] {dagbag.py:538} INFO - Filling up the DagBag from /opt/airflow/dags/mydag.py
[2024-07-01T23:07:41.148+0000] {logging_mixin.py:188} INFO - [2024-07-01T23:07:41.139+0000] {dagbag.py:348} ERROR - Failed to import: /opt/airflow/dags/mydag.py
Traceback (most recent call last):
  File "/home/airflow/.local/lib/python3.8/site-packages/airflow/models/dagbag.py", line 344, in parse
    loader.exec_module(new_module)
  File "<frozen importlib._bootstrap_external>", line 843, in exec_module
  File "<frozen importlib._bootstrap>", line 219, in _call_with_frames_removed
  File "/opt/airflow/dags/mydag.py", line 18, in <module>
    dag = DAG(
  File "/home/airflow/.local/lib/python3.8/site-packages/airflow/models/dag.py", line 498, in __init__
    validate_key(dag_id)
  File "/home/airflow/.local/lib/python3.8/site-packages/airflow/utils/helpers.py", line 57, in validate_key
    raise AirflowException(
airflow.exceptions.AirflowException: The key 'bitcoin data fetching' has to be made of alphanumeric characters, dashes, dots and underscores exclusively
[2024-07-01T23:07:41.149+0000] {processor.py:842} WARNING - No viable dags retrieved from /opt/airflow/dags/mydag.py
[2024-07-01T23:07:41.195+0000] {processor.py:183} INFO - Processing /opt/airflow/dags/mydag.py took 0.090 seconds
[2024-07-01T23:07:56.408+0000] {processor.py:161} INFO - Started process (PID=2319) to work on /opt/airflow/dags/mydag.py
[2024-07-01T23:07:56.411+0000] {processor.py:830} INFO - Processing file /opt/airflow/dags/mydag.py for tasks to queue
[2024-07-01T23:07:56.413+0000] {logging_mixin.py:188} INFO - [2024-07-01T23:07:56.412+0000] {dagbag.py:538} INFO - Filling up the DagBag from /opt/airflow/dags/mydag.py
[2024-07-01T23:07:56.461+0000] {logging_mixin.py:188} INFO - [2024-07-01T23:07:56.453+0000] {dagbag.py:348} ERROR - Failed to import: /opt/airflow/dags/mydag.py
Traceback (most recent call last):
  File "/home/airflow/.local/lib/python3.8/site-packages/airflow/models/dagbag.py", line 344, in parse
    loader.exec_module(new_module)
  File "<frozen importlib._bootstrap_external>", line 843, in exec_module
  File "<frozen importlib._bootstrap>", line 219, in _call_with_frames_removed
  File "/opt/airflow/dags/mydag.py", line 18, in <module>
    dag = DAG(
  File "/home/airflow/.local/lib/python3.8/site-packages/airflow/models/dag.py", line 498, in __init__
    validate_key(dag_id)
  File "/home/airflow/.local/lib/python3.8/site-packages/airflow/utils/helpers.py", line 57, in validate_key
    raise AirflowException(
airflow.exceptions.AirflowException: The key 'bitcoindata fetching' has to be made of alphanumeric characters, dashes, dots and underscores exclusively
[2024-07-01T23:07:56.463+0000] {processor.py:842} WARNING - No viable dags retrieved from /opt/airflow/dags/mydag.py
[2024-07-01T23:07:56.496+0000] {processor.py:183} INFO - Processing /opt/airflow/dags/mydag.py took 0.095 seconds
[2024-07-01T23:07:57.457+0000] {processor.py:161} INFO - Started process (PID=2320) to work on /opt/airflow/dags/mydag.py
[2024-07-01T23:07:57.460+0000] {processor.py:830} INFO - Processing file /opt/airflow/dags/mydag.py for tasks to queue
[2024-07-01T23:07:57.462+0000] {logging_mixin.py:188} INFO - [2024-07-01T23:07:57.461+0000] {dagbag.py:538} INFO - Filling up the DagBag from /opt/airflow/dags/mydag.py
[2024-07-01T23:07:57.503+0000] {logging_mixin.py:188} INFO - [2024-07-01T23:07:57.496+0000] {dagbag.py:348} ERROR - Failed to import: /opt/airflow/dags/mydag.py
Traceback (most recent call last):
  File "/home/airflow/.local/lib/python3.8/site-packages/airflow/models/dagbag.py", line 344, in parse
    loader.exec_module(new_module)
  File "<frozen importlib._bootstrap_external>", line 843, in exec_module
  File "<frozen importlib._bootstrap>", line 219, in _call_with_frames_removed
  File "/opt/airflow/dags/mydag.py", line 18, in <module>
    dag = DAG(
  File "/home/airflow/.local/lib/python3.8/site-packages/airflow/models/dag.py", line 498, in __init__
    validate_key(dag_id)
  File "/home/airflow/.local/lib/python3.8/site-packages/airflow/utils/helpers.py", line 57, in validate_key
    raise AirflowException(
airflow.exceptions.AirflowException: The key 'bitcoin+data fetching' has to be made of alphanumeric characters, dashes, dots and underscores exclusively
[2024-07-01T23:07:57.504+0000] {processor.py:842} WARNING - No viable dags retrieved from /opt/airflow/dags/mydag.py
[2024-07-01T23:07:57.552+0000] {processor.py:183} INFO - Processing /opt/airflow/dags/mydag.py took 0.103 seconds
[2024-07-01T23:07:59.605+0000] {processor.py:161} INFO - Started process (PID=2321) to work on /opt/airflow/dags/mydag.py
[2024-07-01T23:07:59.607+0000] {processor.py:830} INFO - Processing file /opt/airflow/dags/mydag.py for tasks to queue
[2024-07-01T23:07:59.609+0000] {logging_mixin.py:188} INFO - [2024-07-01T23:07:59.608+0000] {dagbag.py:538} INFO - Filling up the DagBag from /opt/airflow/dags/mydag.py
[2024-07-01T23:07:59.659+0000] {logging_mixin.py:188} INFO - [2024-07-01T23:07:59.650+0000] {dagbag.py:348} ERROR - Failed to import: /opt/airflow/dags/mydag.py
Traceback (most recent call last):
  File "/home/airflow/.local/lib/python3.8/site-packages/airflow/models/dagbag.py", line 344, in parse
    loader.exec_module(new_module)
  File "<frozen importlib._bootstrap_external>", line 843, in exec_module
  File "<frozen importlib._bootstrap>", line 219, in _call_with_frames_removed
  File "/opt/airflow/dags/mydag.py", line 18, in <module>
    dag = DAG(
  File "/home/airflow/.local/lib/python3.8/site-packages/airflow/models/dag.py", line 498, in __init__
    validate_key(dag_id)
  File "/home/airflow/.local/lib/python3.8/site-packages/airflow/utils/helpers.py", line 57, in validate_key
    raise AirflowException(
airflow.exceptions.AirflowException: The key 'bitcoin_data fetching' has to be made of alphanumeric characters, dashes, dots and underscores exclusively
[2024-07-01T23:07:59.660+0000] {processor.py:842} WARNING - No viable dags retrieved from /opt/airflow/dags/mydag.py
[2024-07-01T23:07:59.696+0000] {processor.py:183} INFO - Processing /opt/airflow/dags/mydag.py took 0.096 seconds
[2024-07-01T23:08:01.799+0000] {processor.py:161} INFO - Started process (PID=2322) to work on /opt/airflow/dags/mydag.py
[2024-07-01T23:08:01.801+0000] {processor.py:830} INFO - Processing file /opt/airflow/dags/mydag.py for tasks to queue
[2024-07-01T23:08:01.804+0000] {logging_mixin.py:188} INFO - [2024-07-01T23:08:01.803+0000] {dagbag.py:538} INFO - Filling up the DagBag from /opt/airflow/dags/mydag.py
[2024-07-01T23:08:01.866+0000] {logging_mixin.py:188} INFO - [2024-07-01T23:08:01.857+0000] {dagbag.py:348} ERROR - Failed to import: /opt/airflow/dags/mydag.py
Traceback (most recent call last):
  File "/home/airflow/.local/lib/python3.8/site-packages/airflow/models/dagbag.py", line 344, in parse
    loader.exec_module(new_module)
  File "<frozen importlib._bootstrap_external>", line 843, in exec_module
  File "<frozen importlib._bootstrap>", line 219, in _call_with_frames_removed
  File "/opt/airflow/dags/mydag.py", line 26, in <module>
    run_my_function = PythonOperator(
  File "/home/airflow/.local/lib/python3.8/site-packages/airflow/models/baseoperator.py", line 437, in apply_defaults
    result = func(self, **kwargs, default_args=default_args)
  File "/home/airflow/.local/lib/python3.8/site-packages/airflow/operators/python.py", line 186, in __init__
    raise AirflowException("`python_callable` param must be callable")
airflow.exceptions.AirflowException: `python_callable` param must be callable
[2024-07-01T23:08:01.867+0000] {processor.py:842} WARNING - No viable dags retrieved from /opt/airflow/dags/mydag.py
[2024-07-01T23:08:01.915+0000] {processor.py:183} INFO - Processing /opt/airflow/dags/mydag.py took 0.124 seconds
[2024-07-01T23:08:24.004+0000] {processor.py:161} INFO - Started process (PID=2329) to work on /opt/airflow/dags/mydag.py
[2024-07-01T23:08:24.007+0000] {processor.py:830} INFO - Processing file /opt/airflow/dags/mydag.py for tasks to queue
[2024-07-01T23:08:24.009+0000] {logging_mixin.py:188} INFO - [2024-07-01T23:08:24.008+0000] {dagbag.py:538} INFO - Filling up the DagBag from /opt/airflow/dags/mydag.py
[2024-07-01T23:08:24.085+0000] {logging_mixin.py:188} INFO - [2024-07-01T23:08:24.073+0000] {dagbag.py:348} ERROR - Failed to import: /opt/airflow/dags/mydag.py
Traceback (most recent call last):
  File "/home/airflow/.local/lib/python3.8/site-packages/airflow/models/dagbag.py", line 344, in parse
    loader.exec_module(new_module)
  File "<frozen importlib._bootstrap_external>", line 843, in exec_module
  File "<frozen importlib._bootstrap>", line 219, in _call_with_frames_removed
  File "/opt/airflow/dags/mydag.py", line 4, in <module>
    from Scripts import data_etl
  File "/opt/airflow/dags/Scripts/data_etl.py", line 7, in <module>
    from db import WarehouseConnection
ModuleNotFoundError: No module named 'db'
[2024-07-01T23:08:24.089+0000] {processor.py:842} WARNING - No viable dags retrieved from /opt/airflow/dags/mydag.py
[2024-07-01T23:08:24.122+0000] {processor.py:183} INFO - Processing /opt/airflow/dags/mydag.py took 0.125 seconds
[2024-07-01T23:08:33.288+0000] {processor.py:161} INFO - Started process (PID=2330) to work on /opt/airflow/dags/mydag.py
[2024-07-01T23:08:33.289+0000] {processor.py:830} INFO - Processing file /opt/airflow/dags/mydag.py for tasks to queue
[2024-07-01T23:08:33.291+0000] {logging_mixin.py:188} INFO - [2024-07-01T23:08:33.290+0000] {dagbag.py:538} INFO - Filling up the DagBag from /opt/airflow/dags/mydag.py
[2024-07-01T23:08:33.321+0000] {logging_mixin.py:188} INFO - [2024-07-01T23:08:33.318+0000] {dagbag.py:348} ERROR - Failed to import: /opt/airflow/dags/mydag.py
Traceback (most recent call last):
  File "/home/airflow/.local/lib/python3.8/site-packages/airflow/models/dagbag.py", line 344, in parse
    loader.exec_module(new_module)
  File "<frozen importlib._bootstrap_external>", line 839, in exec_module
  File "<frozen importlib._bootstrap_external>", line 976, in get_code
  File "<frozen importlib._bootstrap_external>", line 906, in source_to_code
  File "<frozen importlib._bootstrap>", line 219, in _call_with_frames_removed
  File "/opt/airflow/dags/mydag.py", line 28
    python_callable=,
                    ^
SyntaxError: invalid syntax
[2024-07-01T23:08:33.322+0000] {processor.py:842} WARNING - No viable dags retrieved from /opt/airflow/dags/mydag.py
[2024-07-01T23:08:33.363+0000] {processor.py:183} INFO - Processing /opt/airflow/dags/mydag.py took 0.081 seconds
[2024-07-01T23:08:36.369+0000] {processor.py:161} INFO - Started process (PID=2331) to work on /opt/airflow/dags/mydag.py
[2024-07-01T23:08:36.371+0000] {processor.py:830} INFO - Processing file /opt/airflow/dags/mydag.py for tasks to queue
[2024-07-01T23:08:36.373+0000] {logging_mixin.py:188} INFO - [2024-07-01T23:08:36.373+0000] {dagbag.py:538} INFO - Filling up the DagBag from /opt/airflow/dags/mydag.py
[2024-07-01T23:08:36.459+0000] {logging_mixin.py:188} INFO - [2024-07-01T23:08:36.447+0000] {dagbag.py:348} ERROR - Failed to import: /opt/airflow/dags/mydag.py
Traceback (most recent call last):
  File "/home/airflow/.local/lib/python3.8/site-packages/airflow/models/dagbag.py", line 344, in parse
    loader.exec_module(new_module)
  File "<frozen importlib._bootstrap_external>", line 843, in exec_module
  File "<frozen importlib._bootstrap>", line 219, in _call_with_frames_removed
  File "/opt/airflow/dags/mydag.py", line 4, in <module>
    from Scripts import data_etl
  File "/opt/airflow/dags/Scripts/data_etl.py", line 7, in <module>
    from db import WarehouseConnection
ModuleNotFoundError: No module named 'db'
[2024-07-01T23:08:36.465+0000] {processor.py:842} WARNING - No viable dags retrieved from /opt/airflow/dags/mydag.py
[2024-07-01T23:08:36.501+0000] {processor.py:183} INFO - Processing /opt/airflow/dags/mydag.py took 0.140 seconds
[2024-07-01T23:08:39.603+0000] {processor.py:161} INFO - Started process (PID=2332) to work on /opt/airflow/dags/mydag.py
[2024-07-01T23:08:39.605+0000] {processor.py:830} INFO - Processing file /opt/airflow/dags/mydag.py for tasks to queue
[2024-07-01T23:08:39.607+0000] {logging_mixin.py:188} INFO - [2024-07-01T23:08:39.606+0000] {dagbag.py:538} INFO - Filling up the DagBag from /opt/airflow/dags/mydag.py
[2024-07-01T23:08:39.632+0000] {logging_mixin.py:188} INFO - [2024-07-01T23:08:39.630+0000] {dagbag.py:348} ERROR - Failed to import: /opt/airflow/dags/mydag.py
Traceback (most recent call last):
  File "/home/airflow/.local/lib/python3.8/site-packages/airflow/models/dagbag.py", line 344, in parse
    loader.exec_module(new_module)
  File "<frozen importlib._bootstrap_external>", line 839, in exec_module
  File "<frozen importlib._bootstrap_external>", line 976, in get_code
  File "<frozen importlib._bootstrap_external>", line 906, in source_to_code
  File "<frozen importlib._bootstrap>", line 219, in _call_with_frames_removed
  File "/opt/airflow/dags/mydag.py", line 28
    python_callable=data_etl.,
                             ^
SyntaxError: invalid syntax
[2024-07-01T23:08:39.633+0000] {processor.py:842} WARNING - No viable dags retrieved from /opt/airflow/dags/mydag.py
[2024-07-01T23:08:39.667+0000] {processor.py:183} INFO - Processing /opt/airflow/dags/mydag.py took 0.071 seconds
[2024-07-01T23:08:41.651+0000] {processor.py:161} INFO - Started process (PID=2333) to work on /opt/airflow/dags/mydag.py
[2024-07-01T23:08:41.653+0000] {processor.py:830} INFO - Processing file /opt/airflow/dags/mydag.py for tasks to queue
[2024-07-01T23:08:41.655+0000] {logging_mixin.py:188} INFO - [2024-07-01T23:08:41.654+0000] {dagbag.py:538} INFO - Filling up the DagBag from /opt/airflow/dags/mydag.py
[2024-07-01T23:08:41.739+0000] {logging_mixin.py:188} INFO - [2024-07-01T23:08:41.727+0000] {dagbag.py:348} ERROR - Failed to import: /opt/airflow/dags/mydag.py
Traceback (most recent call last):
  File "/home/airflow/.local/lib/python3.8/site-packages/airflow/models/dagbag.py", line 344, in parse
    loader.exec_module(new_module)
  File "<frozen importlib._bootstrap_external>", line 843, in exec_module
  File "<frozen importlib._bootstrap>", line 219, in _call_with_frames_removed
  File "/opt/airflow/dags/mydag.py", line 4, in <module>
    from Scripts import data_etl
  File "/opt/airflow/dags/Scripts/data_etl.py", line 7, in <module>
    from db import WarehouseConnection
ModuleNotFoundError: No module named 'db'
[2024-07-01T23:08:41.744+0000] {processor.py:842} WARNING - No viable dags retrieved from /opt/airflow/dags/mydag.py
[2024-07-01T23:08:41.793+0000] {processor.py:183} INFO - Processing /opt/airflow/dags/mydag.py took 0.149 seconds
[2024-07-01T23:08:44.794+0000] {processor.py:161} INFO - Started process (PID=2334) to work on /opt/airflow/dags/mydag.py
[2024-07-01T23:08:44.797+0000] {processor.py:830} INFO - Processing file /opt/airflow/dags/mydag.py for tasks to queue
[2024-07-01T23:08:44.799+0000] {logging_mixin.py:188} INFO - [2024-07-01T23:08:44.798+0000] {dagbag.py:538} INFO - Filling up the DagBag from /opt/airflow/dags/mydag.py
[2024-07-01T23:08:44.890+0000] {logging_mixin.py:188} INFO - [2024-07-01T23:08:44.876+0000] {dagbag.py:348} ERROR - Failed to import: /opt/airflow/dags/mydag.py
Traceback (most recent call last):
  File "/home/airflow/.local/lib/python3.8/site-packages/airflow/models/dagbag.py", line 344, in parse
    loader.exec_module(new_module)
  File "<frozen importlib._bootstrap_external>", line 843, in exec_module
  File "<frozen importlib._bootstrap>", line 219, in _call_with_frames_removed
  File "/opt/airflow/dags/mydag.py", line 4, in <module>
    from Scripts import data_etl
  File "/opt/airflow/dags/Scripts/data_etl.py", line 7, in <module>
    from db import WarehouseConnection
ModuleNotFoundError: No module named 'db'
[2024-07-01T23:08:44.895+0000] {processor.py:842} WARNING - No viable dags retrieved from /opt/airflow/dags/mydag.py
[2024-07-01T23:08:44.938+0000] {processor.py:183} INFO - Processing /opt/airflow/dags/mydag.py took 0.152 seconds
[2024-07-01T23:08:45.900+0000] {processor.py:161} INFO - Started process (PID=2335) to work on /opt/airflow/dags/mydag.py
[2024-07-01T23:08:45.902+0000] {processor.py:830} INFO - Processing file /opt/airflow/dags/mydag.py for tasks to queue
[2024-07-01T23:08:45.905+0000] {logging_mixin.py:188} INFO - [2024-07-01T23:08:45.904+0000] {dagbag.py:538} INFO - Filling up the DagBag from /opt/airflow/dags/mydag.py
[2024-07-01T23:08:45.978+0000] {logging_mixin.py:188} INFO - [2024-07-01T23:08:45.967+0000] {dagbag.py:348} ERROR - Failed to import: /opt/airflow/dags/mydag.py
Traceback (most recent call last):
  File "/home/airflow/.local/lib/python3.8/site-packages/airflow/models/dagbag.py", line 344, in parse
    loader.exec_module(new_module)
  File "<frozen importlib._bootstrap_external>", line 843, in exec_module
  File "<frozen importlib._bootstrap>", line 219, in _call_with_frames_removed
  File "/opt/airflow/dags/mydag.py", line 4, in <module>
    from Scripts import data_etl
  File "/opt/airflow/dags/Scripts/data_etl.py", line 7, in <module>
    from db import WarehouseConnection
ModuleNotFoundError: No module named 'db'
[2024-07-01T23:08:45.982+0000] {processor.py:842} WARNING - No viable dags retrieved from /opt/airflow/dags/mydag.py
[2024-07-01T23:08:46.013+0000] {processor.py:183} INFO - Processing /opt/airflow/dags/mydag.py took 0.119 seconds
[2024-07-01T23:08:47.082+0000] {processor.py:161} INFO - Started process (PID=2336) to work on /opt/airflow/dags/mydag.py
[2024-07-01T23:08:47.084+0000] {processor.py:830} INFO - Processing file /opt/airflow/dags/mydag.py for tasks to queue
[2024-07-01T23:08:47.086+0000] {logging_mixin.py:188} INFO - [2024-07-01T23:08:47.086+0000] {dagbag.py:538} INFO - Filling up the DagBag from /opt/airflow/dags/mydag.py
[2024-07-01T23:08:47.171+0000] {logging_mixin.py:188} INFO - [2024-07-01T23:08:47.159+0000] {dagbag.py:348} ERROR - Failed to import: /opt/airflow/dags/mydag.py
Traceback (most recent call last):
  File "/home/airflow/.local/lib/python3.8/site-packages/airflow/models/dagbag.py", line 344, in parse
    loader.exec_module(new_module)
  File "<frozen importlib._bootstrap_external>", line 843, in exec_module
  File "<frozen importlib._bootstrap>", line 219, in _call_with_frames_removed
  File "/opt/airflow/dags/mydag.py", line 4, in <module>
    from Scripts import data_etl
  File "/opt/airflow/dags/Scripts/data_etl.py", line 7, in <module>
    from db import WarehouseConnection
ModuleNotFoundError: No module named 'db'
[2024-07-01T23:08:47.175+0000] {processor.py:842} WARNING - No viable dags retrieved from /opt/airflow/dags/mydag.py
[2024-07-01T23:08:47.217+0000] {processor.py:183} INFO - Processing /opt/airflow/dags/mydag.py took 0.140 seconds
[2024-07-01T23:09:17.362+0000] {processor.py:161} INFO - Started process (PID=2343) to work on /opt/airflow/dags/mydag.py
[2024-07-01T23:09:17.363+0000] {processor.py:830} INFO - Processing file /opt/airflow/dags/mydag.py for tasks to queue
[2024-07-01T23:09:17.366+0000] {logging_mixin.py:188} INFO - [2024-07-01T23:09:17.365+0000] {dagbag.py:538} INFO - Filling up the DagBag from /opt/airflow/dags/mydag.py
[2024-07-01T23:09:17.481+0000] {logging_mixin.py:188} INFO - [2024-07-01T23:09:17.465+0000] {dagbag.py:348} ERROR - Failed to import: /opt/airflow/dags/mydag.py
Traceback (most recent call last):
  File "/home/airflow/.local/lib/python3.8/site-packages/airflow/models/dagbag.py", line 344, in parse
    loader.exec_module(new_module)
  File "<frozen importlib._bootstrap_external>", line 843, in exec_module
  File "<frozen importlib._bootstrap>", line 219, in _call_with_frames_removed
  File "/opt/airflow/dags/mydag.py", line 4, in <module>
    from Scripts import data_etl
  File "/opt/airflow/dags/Scripts/data_etl.py", line 7, in <module>
    from db import WarehouseConnection
ModuleNotFoundError: No module named 'db'
[2024-07-01T23:09:17.487+0000] {processor.py:842} WARNING - No viable dags retrieved from /opt/airflow/dags/mydag.py
[2024-07-01T23:09:17.534+0000] {processor.py:183} INFO - Processing /opt/airflow/dags/mydag.py took 0.179 seconds
[2024-07-01T23:09:47.880+0000] {processor.py:161} INFO - Started process (PID=2350) to work on /opt/airflow/dags/mydag.py
[2024-07-01T23:09:47.883+0000] {processor.py:830} INFO - Processing file /opt/airflow/dags/mydag.py for tasks to queue
[2024-07-01T23:09:47.886+0000] {logging_mixin.py:188} INFO - [2024-07-01T23:09:47.885+0000] {dagbag.py:538} INFO - Filling up the DagBag from /opt/airflow/dags/mydag.py
[2024-07-01T23:09:48.071+0000] {logging_mixin.py:188} INFO - [2024-07-01T23:09:48.052+0000] {dagbag.py:348} ERROR - Failed to import: /opt/airflow/dags/mydag.py
Traceback (most recent call last):
  File "/home/airflow/.local/lib/python3.8/site-packages/airflow/models/dagbag.py", line 344, in parse
    loader.exec_module(new_module)
  File "<frozen importlib._bootstrap_external>", line 843, in exec_module
  File "<frozen importlib._bootstrap>", line 219, in _call_with_frames_removed
  File "/opt/airflow/dags/mydag.py", line 4, in <module>
    from Scripts import data_etl
  File "/opt/airflow/dags/Scripts/data_etl.py", line 8, in <module>
    from Scripts.credentials import get_warehouse_creds
  File "/opt/airflow/dags/Scripts/credentials.py", line 2, in <module>
    from db import DBConnection
ModuleNotFoundError: No module named 'db'
[2024-07-01T23:09:48.076+0000] {processor.py:842} WARNING - No viable dags retrieved from /opt/airflow/dags/mydag.py
[2024-07-01T23:09:48.113+0000] {processor.py:183} INFO - Processing /opt/airflow/dags/mydag.py took 0.247 seconds
[2024-07-01T23:10:18.219+0000] {processor.py:161} INFO - Started process (PID=2357) to work on /opt/airflow/dags/mydag.py
[2024-07-01T23:10:18.221+0000] {processor.py:830} INFO - Processing file /opt/airflow/dags/mydag.py for tasks to queue
[2024-07-01T23:10:18.224+0000] {logging_mixin.py:188} INFO - [2024-07-01T23:10:18.223+0000] {dagbag.py:538} INFO - Filling up the DagBag from /opt/airflow/dags/mydag.py
[2024-07-01T23:10:18.323+0000] {logging_mixin.py:188} INFO - [2024-07-01T23:10:18.306+0000] {dagbag.py:348} ERROR - Failed to import: /opt/airflow/dags/mydag.py
Traceback (most recent call last):
  File "/home/airflow/.local/lib/python3.8/site-packages/airflow/models/dagbag.py", line 344, in parse
    loader.exec_module(new_module)
  File "<frozen importlib._bootstrap_external>", line 843, in exec_module
  File "<frozen importlib._bootstrap>", line 219, in _call_with_frames_removed
  File "/opt/airflow/dags/mydag.py", line 4, in <module>
    from Scripts import data_etl
  File "/opt/airflow/dags/Scripts/data_etl.py", line 8, in <module>
    from Scripts.credentials import get_warehouse_creds
  File "/opt/airflow/dags/Scripts/credentials.py", line 2, in <module>
    from db import DBConnection
ModuleNotFoundError: No module named 'db'
[2024-07-01T23:10:18.328+0000] {processor.py:842} WARNING - No viable dags retrieved from /opt/airflow/dags/mydag.py
[2024-07-01T23:10:18.365+0000] {processor.py:183} INFO - Processing /opt/airflow/dags/mydag.py took 0.155 seconds
[2024-07-01T23:10:48.578+0000] {processor.py:161} INFO - Started process (PID=2364) to work on /opt/airflow/dags/mydag.py
[2024-07-01T23:10:48.581+0000] {processor.py:830} INFO - Processing file /opt/airflow/dags/mydag.py for tasks to queue
[2024-07-01T23:10:48.583+0000] {logging_mixin.py:188} INFO - [2024-07-01T23:10:48.582+0000] {dagbag.py:538} INFO - Filling up the DagBag from /opt/airflow/dags/mydag.py
[2024-07-01T23:10:48.773+0000] {logging_mixin.py:188} INFO - [2024-07-01T23:10:48.697+0000] {dagbag.py:348} ERROR - Failed to import: /opt/airflow/dags/mydag.py
Traceback (most recent call last):
  File "/home/airflow/.local/lib/python3.8/site-packages/airflow/models/dagbag.py", line 344, in parse
    loader.exec_module(new_module)
  File "<frozen importlib._bootstrap_external>", line 843, in exec_module
  File "<frozen importlib._bootstrap>", line 219, in _call_with_frames_removed
  File "/opt/airflow/dags/mydag.py", line 4, in <module>
    from Scripts import data_etl
  File "/opt/airflow/dags/Scripts/data_etl.py", line 8, in <module>
    from Scripts.credentials import get_warehouse_creds
  File "/opt/airflow/dags/Scripts/credentials.py", line 2, in <module>
    from db import DBConnection
ModuleNotFoundError: No module named 'db'
[2024-07-01T23:10:48.820+0000] {processor.py:842} WARNING - No viable dags retrieved from /opt/airflow/dags/mydag.py
[2024-07-01T23:10:48.878+0000] {processor.py:183} INFO - Processing /opt/airflow/dags/mydag.py took 0.313 seconds
[2024-07-01T23:11:18.965+0000] {processor.py:161} INFO - Started process (PID=2372) to work on /opt/airflow/dags/mydag.py
[2024-07-01T23:11:18.967+0000] {processor.py:830} INFO - Processing file /opt/airflow/dags/mydag.py for tasks to queue
[2024-07-01T23:11:18.969+0000] {logging_mixin.py:188} INFO - [2024-07-01T23:11:18.968+0000] {dagbag.py:538} INFO - Filling up the DagBag from /opt/airflow/dags/mydag.py
[2024-07-01T23:11:19.708+0000] {logging_mixin.py:188} INFO - postgress link postgresql://postgres:12345@localhost:5432/postgres
[2024-07-01T23:11:19.730+0000] {logging_mixin.py:188} INFO - [2024-07-01T23:11:19.711+0000] {dagbag.py:348} ERROR - Failed to import: /opt/airflow/dags/mydag.py
Traceback (most recent call last):
  File "/home/airflow/.local/lib/python3.8/site-packages/airflow/models/dagbag.py", line 344, in parse
    loader.exec_module(new_module)
  File "<frozen importlib._bootstrap_external>", line 843, in exec_module
  File "<frozen importlib._bootstrap>", line 219, in _call_with_frames_removed
  File "/opt/airflow/dags/mydag.py", line 28, in <module>
    python_callable=data_etl.run(),
  File "/opt/airflow/dags/Scripts/data_etl.py", line 61, in run
    with WarehouseConnection(get_warehouse_creds()).managed_cursor() as curr:
  File "/usr/local/lib/python3.8/contextlib.py", line 113, in __enter__
    return next(self.gen)
  File "/opt/airflow/dags/Scripts/db.py", line 26, in managed_cursor
    self.conn = psycopg2.connect(self.conn_url)
  File "/home/airflow/.local/lib/python3.8/site-packages/psycopg2/__init__.py", line 122, in connect
    conn = _connect(dsn, connection_factory=connection_factory, **kwasync)
psycopg2.OperationalError: connection to server at "localhost" (::1), port 5432 failed: Connection refused
	Is the server running on that host and accepting TCP/IP connections?
connection to server at "localhost" (127.0.0.1), port 5432 failed: Connection refused
	Is the server running on that host and accepting TCP/IP connections?
[2024-07-01T23:11:19.733+0000] {processor.py:842} WARNING - No viable dags retrieved from /opt/airflow/dags/mydag.py
[2024-07-01T23:11:19.780+0000] {processor.py:183} INFO - Processing /opt/airflow/dags/mydag.py took 0.821 seconds
[2024-07-01T23:11:50.111+0000] {processor.py:161} INFO - Started process (PID=2379) to work on /opt/airflow/dags/mydag.py
[2024-07-01T23:11:50.113+0000] {processor.py:830} INFO - Processing file /opt/airflow/dags/mydag.py for tasks to queue
[2024-07-01T23:11:50.115+0000] {logging_mixin.py:188} INFO - [2024-07-01T23:11:50.114+0000] {dagbag.py:538} INFO - Filling up the DagBag from /opt/airflow/dags/mydag.py
[2024-07-01T23:11:50.785+0000] {logging_mixin.py:188} INFO - postgress link postgresql://postgres:12345@localhost:5432/postgres
[2024-07-01T23:11:50.825+0000] {logging_mixin.py:188} INFO - [2024-07-01T23:11:50.791+0000] {dagbag.py:348} ERROR - Failed to import: /opt/airflow/dags/mydag.py
Traceback (most recent call last):
  File "/home/airflow/.local/lib/python3.8/site-packages/airflow/models/dagbag.py", line 344, in parse
    loader.exec_module(new_module)
  File "<frozen importlib._bootstrap_external>", line 843, in exec_module
  File "<frozen importlib._bootstrap>", line 219, in _call_with_frames_removed
  File "/opt/airflow/dags/mydag.py", line 28, in <module>
    python_callable=data_etl.run(),
  File "/opt/airflow/dags/Scripts/data_etl.py", line 61, in run
    with WarehouseConnection(get_warehouse_creds()).managed_cursor() as curr:
  File "/usr/local/lib/python3.8/contextlib.py", line 113, in __enter__
    return next(self.gen)
  File "/opt/airflow/dags/Scripts/db.py", line 26, in managed_cursor
    self.conn = psycopg2.connect(self.conn_url)
  File "/home/airflow/.local/lib/python3.8/site-packages/psycopg2/__init__.py", line 122, in connect
    conn = _connect(dsn, connection_factory=connection_factory, **kwasync)
psycopg2.OperationalError: connection to server at "localhost" (::1), port 5432 failed: Connection refused
	Is the server running on that host and accepting TCP/IP connections?
connection to server at "localhost" (127.0.0.1), port 5432 failed: Connection refused
	Is the server running on that host and accepting TCP/IP connections?
[2024-07-01T23:11:50.829+0000] {processor.py:842} WARNING - No viable dags retrieved from /opt/airflow/dags/mydag.py
[2024-07-01T23:11:50.870+0000] {processor.py:183} INFO - Processing /opt/airflow/dags/mydag.py took 0.765 seconds
[2024-07-01T23:12:21.367+0000] {processor.py:161} INFO - Started process (PID=2392) to work on /opt/airflow/dags/mydag.py
[2024-07-01T23:12:21.369+0000] {processor.py:830} INFO - Processing file /opt/airflow/dags/mydag.py for tasks to queue
[2024-07-01T23:12:21.371+0000] {logging_mixin.py:188} INFO - [2024-07-01T23:12:21.370+0000] {dagbag.py:538} INFO - Filling up the DagBag from /opt/airflow/dags/mydag.py
[2024-07-01T23:12:22.191+0000] {logging_mixin.py:188} INFO - postgress link postgresql://postgres:12345@localhost:5432/postgres
[2024-07-01T23:12:22.215+0000] {logging_mixin.py:188} INFO - [2024-07-01T23:12:22.194+0000] {dagbag.py:348} ERROR - Failed to import: /opt/airflow/dags/mydag.py
Traceback (most recent call last):
  File "/home/airflow/.local/lib/python3.8/site-packages/airflow/models/dagbag.py", line 344, in parse
    loader.exec_module(new_module)
  File "<frozen importlib._bootstrap_external>", line 843, in exec_module
  File "<frozen importlib._bootstrap>", line 219, in _call_with_frames_removed
  File "/opt/airflow/dags/mydag.py", line 28, in <module>
    python_callable=data_etl.run(),
  File "/opt/airflow/dags/Scripts/data_etl.py", line 61, in run
    with WarehouseConnection(get_warehouse_creds()).managed_cursor() as curr:
  File "/usr/local/lib/python3.8/contextlib.py", line 113, in __enter__
    return next(self.gen)
  File "/opt/airflow/dags/Scripts/db.py", line 26, in managed_cursor
    self.conn = psycopg2.connect(self.conn_url)
  File "/home/airflow/.local/lib/python3.8/site-packages/psycopg2/__init__.py", line 122, in connect
    conn = _connect(dsn, connection_factory=connection_factory, **kwasync)
psycopg2.OperationalError: connection to server at "localhost" (::1), port 5432 failed: Connection refused
	Is the server running on that host and accepting TCP/IP connections?
connection to server at "localhost" (127.0.0.1), port 5432 failed: Connection refused
	Is the server running on that host and accepting TCP/IP connections?
[2024-07-01T23:12:22.217+0000] {processor.py:842} WARNING - No viable dags retrieved from /opt/airflow/dags/mydag.py
[2024-07-01T23:12:22.256+0000] {processor.py:183} INFO - Processing /opt/airflow/dags/mydag.py took 0.895 seconds
[2024-07-01T23:12:52.588+0000] {processor.py:161} INFO - Started process (PID=2399) to work on /opt/airflow/dags/mydag.py
[2024-07-01T23:12:52.590+0000] {processor.py:830} INFO - Processing file /opt/airflow/dags/mydag.py for tasks to queue
[2024-07-01T23:12:52.592+0000] {logging_mixin.py:188} INFO - [2024-07-01T23:12:52.592+0000] {dagbag.py:538} INFO - Filling up the DagBag from /opt/airflow/dags/mydag.py
[2024-07-01T23:12:53.758+0000] {logging_mixin.py:188} INFO - postgress link postgresql://postgres:12345@localhost:5432/postgres
[2024-07-01T23:12:53.785+0000] {logging_mixin.py:188} INFO - [2024-07-01T23:12:53.762+0000] {dagbag.py:348} ERROR - Failed to import: /opt/airflow/dags/mydag.py
Traceback (most recent call last):
  File "/home/airflow/.local/lib/python3.8/site-packages/airflow/models/dagbag.py", line 344, in parse
    loader.exec_module(new_module)
  File "<frozen importlib._bootstrap_external>", line 843, in exec_module
  File "<frozen importlib._bootstrap>", line 219, in _call_with_frames_removed
  File "/opt/airflow/dags/mydag.py", line 28, in <module>
    python_callable=data_etl.run(),
  File "/opt/airflow/dags/Scripts/data_etl.py", line 61, in run
    with WarehouseConnection(get_warehouse_creds()).managed_cursor() as curr:
  File "/usr/local/lib/python3.8/contextlib.py", line 113, in __enter__
    return next(self.gen)
  File "/opt/airflow/dags/Scripts/db.py", line 26, in managed_cursor
    self.conn = psycopg2.connect(self.conn_url)
  File "/home/airflow/.local/lib/python3.8/site-packages/psycopg2/__init__.py", line 122, in connect
    conn = _connect(dsn, connection_factory=connection_factory, **kwasync)
psycopg2.OperationalError: connection to server at "localhost" (::1), port 5432 failed: Connection refused
	Is the server running on that host and accepting TCP/IP connections?
connection to server at "localhost" (127.0.0.1), port 5432 failed: Connection refused
	Is the server running on that host and accepting TCP/IP connections?
[2024-07-01T23:12:53.788+0000] {processor.py:842} WARNING - No viable dags retrieved from /opt/airflow/dags/mydag.py
[2024-07-01T23:12:53.820+0000] {processor.py:183} INFO - Processing /opt/airflow/dags/mydag.py took 1.240 seconds
[2024-07-01T23:13:24.080+0000] {processor.py:161} INFO - Started process (PID=2406) to work on /opt/airflow/dags/mydag.py
[2024-07-01T23:13:24.083+0000] {processor.py:830} INFO - Processing file /opt/airflow/dags/mydag.py for tasks to queue
[2024-07-01T23:13:24.086+0000] {logging_mixin.py:188} INFO - [2024-07-01T23:13:24.085+0000] {dagbag.py:538} INFO - Filling up the DagBag from /opt/airflow/dags/mydag.py
[2024-07-01T23:13:25.277+0000] {logging_mixin.py:188} INFO - postgress link postgresql://postgres:12345@localhost:5432/postgres
[2024-07-01T23:13:25.318+0000] {logging_mixin.py:188} INFO - [2024-07-01T23:13:25.295+0000] {dagbag.py:348} ERROR - Failed to import: /opt/airflow/dags/mydag.py
Traceback (most recent call last):
  File "/home/airflow/.local/lib/python3.8/site-packages/airflow/models/dagbag.py", line 344, in parse
    loader.exec_module(new_module)
  File "<frozen importlib._bootstrap_external>", line 843, in exec_module
  File "<frozen importlib._bootstrap>", line 219, in _call_with_frames_removed
  File "/opt/airflow/dags/mydag.py", line 28, in <module>
    python_callable=data_etl.run(),
  File "/opt/airflow/dags/Scripts/data_etl.py", line 61, in run
    with WarehouseConnection(get_warehouse_creds()).managed_cursor() as curr:
  File "/usr/local/lib/python3.8/contextlib.py", line 113, in __enter__
    return next(self.gen)
  File "/opt/airflow/dags/Scripts/db.py", line 26, in managed_cursor
    self.conn = psycopg2.connect(self.conn_url)
  File "/home/airflow/.local/lib/python3.8/site-packages/psycopg2/__init__.py", line 122, in connect
    conn = _connect(dsn, connection_factory=connection_factory, **kwasync)
psycopg2.OperationalError: connection to server at "localhost" (::1), port 5432 failed: Connection refused
	Is the server running on that host and accepting TCP/IP connections?
connection to server at "localhost" (127.0.0.1), port 5432 failed: Connection refused
	Is the server running on that host and accepting TCP/IP connections?
[2024-07-01T23:13:25.323+0000] {processor.py:842} WARNING - No viable dags retrieved from /opt/airflow/dags/mydag.py
[2024-07-01T23:13:25.366+0000] {processor.py:183} INFO - Processing /opt/airflow/dags/mydag.py took 1.294 seconds
[2024-07-01T23:13:55.679+0000] {processor.py:161} INFO - Started process (PID=2413) to work on /opt/airflow/dags/mydag.py
[2024-07-01T23:13:55.681+0000] {processor.py:830} INFO - Processing file /opt/airflow/dags/mydag.py for tasks to queue
[2024-07-01T23:13:55.683+0000] {logging_mixin.py:188} INFO - [2024-07-01T23:13:55.682+0000] {dagbag.py:538} INFO - Filling up the DagBag from /opt/airflow/dags/mydag.py
[2024-07-01T23:13:56.287+0000] {logging_mixin.py:188} INFO - postgress link postgresql://postgres:12345@localhost:5432/postgres
[2024-07-01T23:13:56.310+0000] {logging_mixin.py:188} INFO - [2024-07-01T23:13:56.289+0000] {dagbag.py:348} ERROR - Failed to import: /opt/airflow/dags/mydag.py
Traceback (most recent call last):
  File "/home/airflow/.local/lib/python3.8/site-packages/airflow/models/dagbag.py", line 344, in parse
    loader.exec_module(new_module)
  File "<frozen importlib._bootstrap_external>", line 843, in exec_module
  File "<frozen importlib._bootstrap>", line 219, in _call_with_frames_removed
  File "/opt/airflow/dags/mydag.py", line 28, in <module>
    python_callable=data_etl.run(),
  File "/opt/airflow/dags/Scripts/data_etl.py", line 61, in run
    with WarehouseConnection(get_warehouse_creds()).managed_cursor() as curr:
  File "/usr/local/lib/python3.8/contextlib.py", line 113, in __enter__
    return next(self.gen)
  File "/opt/airflow/dags/Scripts/db.py", line 26, in managed_cursor
    self.conn = psycopg2.connect(self.conn_url)
  File "/home/airflow/.local/lib/python3.8/site-packages/psycopg2/__init__.py", line 122, in connect
    conn = _connect(dsn, connection_factory=connection_factory, **kwasync)
psycopg2.OperationalError: connection to server at "localhost" (::1), port 5432 failed: Connection refused
	Is the server running on that host and accepting TCP/IP connections?
connection to server at "localhost" (127.0.0.1), port 5432 failed: Connection refused
	Is the server running on that host and accepting TCP/IP connections?
[2024-07-01T23:13:56.313+0000] {processor.py:842} WARNING - No viable dags retrieved from /opt/airflow/dags/mydag.py
[2024-07-01T23:13:56.352+0000] {processor.py:183} INFO - Processing /opt/airflow/dags/mydag.py took 0.680 seconds
[2024-07-01T23:14:26.642+0000] {processor.py:161} INFO - Started process (PID=2420) to work on /opt/airflow/dags/mydag.py
[2024-07-01T23:14:26.644+0000] {processor.py:830} INFO - Processing file /opt/airflow/dags/mydag.py for tasks to queue
[2024-07-01T23:14:26.646+0000] {logging_mixin.py:188} INFO - [2024-07-01T23:14:26.645+0000] {dagbag.py:538} INFO - Filling up the DagBag from /opt/airflow/dags/mydag.py
[2024-07-01T23:14:27.232+0000] {logging_mixin.py:188} INFO - postgress link postgresql://postgres:12345@localhost:5432/postgres
[2024-07-01T23:14:27.274+0000] {logging_mixin.py:188} INFO - [2024-07-01T23:14:27.238+0000] {dagbag.py:348} ERROR - Failed to import: /opt/airflow/dags/mydag.py
Traceback (most recent call last):
  File "/home/airflow/.local/lib/python3.8/site-packages/airflow/models/dagbag.py", line 344, in parse
    loader.exec_module(new_module)
  File "<frozen importlib._bootstrap_external>", line 843, in exec_module
  File "<frozen importlib._bootstrap>", line 219, in _call_with_frames_removed
  File "/opt/airflow/dags/mydag.py", line 28, in <module>
    python_callable=data_etl.run(),
  File "/opt/airflow/dags/Scripts/data_etl.py", line 61, in run
    with WarehouseConnection(get_warehouse_creds()).managed_cursor() as curr:
  File "/usr/local/lib/python3.8/contextlib.py", line 113, in __enter__
    return next(self.gen)
  File "/opt/airflow/dags/Scripts/db.py", line 26, in managed_cursor
    self.conn = psycopg2.connect(self.conn_url)
  File "/home/airflow/.local/lib/python3.8/site-packages/psycopg2/__init__.py", line 122, in connect
    conn = _connect(dsn, connection_factory=connection_factory, **kwasync)
psycopg2.OperationalError: connection to server at "localhost" (::1), port 5432 failed: Connection refused
	Is the server running on that host and accepting TCP/IP connections?
connection to server at "localhost" (127.0.0.1), port 5432 failed: Connection refused
	Is the server running on that host and accepting TCP/IP connections?
[2024-07-01T23:14:27.278+0000] {processor.py:842} WARNING - No viable dags retrieved from /opt/airflow/dags/mydag.py
[2024-07-01T23:14:27.332+0000] {processor.py:183} INFO - Processing /opt/airflow/dags/mydag.py took 0.695 seconds
[2024-07-01T23:14:57.681+0000] {processor.py:161} INFO - Started process (PID=2427) to work on /opt/airflow/dags/mydag.py
[2024-07-01T23:14:57.683+0000] {processor.py:830} INFO - Processing file /opt/airflow/dags/mydag.py for tasks to queue
[2024-07-01T23:14:57.685+0000] {logging_mixin.py:188} INFO - [2024-07-01T23:14:57.685+0000] {dagbag.py:538} INFO - Filling up the DagBag from /opt/airflow/dags/mydag.py
[2024-07-01T23:14:58.315+0000] {logging_mixin.py:188} INFO - postgress link postgresql://postgres:12345@192.168.176.1:5432/postgres
[2024-07-01T23:14:58.404+0000] {logging_mixin.py:188} INFO - [2024-07-01T23:14:58.383+0000] {dagbag.py:348} ERROR - Failed to import: /opt/airflow/dags/mydag.py
Traceback (most recent call last):
  File "/home/airflow/.local/lib/python3.8/site-packages/airflow/models/dagbag.py", line 344, in parse
    loader.exec_module(new_module)
  File "<frozen importlib._bootstrap_external>", line 843, in exec_module
  File "<frozen importlib._bootstrap>", line 219, in _call_with_frames_removed
  File "/opt/airflow/dags/mydag.py", line 28, in <module>
    python_callable=data_etl.run(),
  File "/opt/airflow/dags/Scripts/data_etl.py", line 61, in run
    with WarehouseConnection(get_warehouse_creds()).managed_cursor() as curr:
  File "/usr/local/lib/python3.8/contextlib.py", line 113, in __enter__
    return next(self.gen)
  File "/opt/airflow/dags/Scripts/db.py", line 26, in managed_cursor
    self.conn = psycopg2.connect(self.conn_url)
  File "/home/airflow/.local/lib/python3.8/site-packages/psycopg2/__init__.py", line 122, in connect
    conn = _connect(dsn, connection_factory=connection_factory, **kwasync)
psycopg2.OperationalError: connection to server at "192.168.176.1", port 5432 failed: FATAL:  no pg_hba.conf entry for host "192.168.176.1", user "postgres", database "postgres", no encryption
[2024-07-01T23:14:58.407+0000] {processor.py:842} WARNING - No viable dags retrieved from /opt/airflow/dags/mydag.py
[2024-07-01T23:14:58.438+0000] {processor.py:183} INFO - Processing /opt/airflow/dags/mydag.py took 0.766 seconds
[2024-07-01T23:15:28.794+0000] {processor.py:161} INFO - Started process (PID=2434) to work on /opt/airflow/dags/mydag.py
[2024-07-01T23:15:28.795+0000] {processor.py:830} INFO - Processing file /opt/airflow/dags/mydag.py for tasks to queue
[2024-07-01T23:15:28.798+0000] {logging_mixin.py:188} INFO - [2024-07-01T23:15:28.797+0000] {dagbag.py:538} INFO - Filling up the DagBag from /opt/airflow/dags/mydag.py
[2024-07-01T23:15:29.426+0000] {logging_mixin.py:188} INFO - postgress link postgresql://postgres:12345@192.168.176.1:5432/postgres
[2024-07-01T23:15:29.509+0000] {logging_mixin.py:188} INFO - [2024-07-01T23:15:29.489+0000] {dagbag.py:348} ERROR - Failed to import: /opt/airflow/dags/mydag.py
Traceback (most recent call last):
  File "/home/airflow/.local/lib/python3.8/site-packages/airflow/models/dagbag.py", line 344, in parse
    loader.exec_module(new_module)
  File "<frozen importlib._bootstrap_external>", line 843, in exec_module
  File "<frozen importlib._bootstrap>", line 219, in _call_with_frames_removed
  File "/opt/airflow/dags/mydag.py", line 28, in <module>
    python_callable=data_etl.run(),
  File "/opt/airflow/dags/Scripts/data_etl.py", line 61, in run
    with WarehouseConnection(get_warehouse_creds()).managed_cursor() as curr:
  File "/usr/local/lib/python3.8/contextlib.py", line 113, in __enter__
    return next(self.gen)
  File "/opt/airflow/dags/Scripts/db.py", line 26, in managed_cursor
    self.conn = psycopg2.connect(self.conn_url)
  File "/home/airflow/.local/lib/python3.8/site-packages/psycopg2/__init__.py", line 122, in connect
    conn = _connect(dsn, connection_factory=connection_factory, **kwasync)
psycopg2.OperationalError: connection to server at "192.168.176.1", port 5432 failed: FATAL:  no pg_hba.conf entry for host "192.168.176.1", user "postgres", database "postgres", no encryption
[2024-07-01T23:15:29.512+0000] {processor.py:842} WARNING - No viable dags retrieved from /opt/airflow/dags/mydag.py
[2024-07-01T23:15:29.545+0000] {processor.py:183} INFO - Processing /opt/airflow/dags/mydag.py took 0.758 seconds
[2024-07-01T23:15:59.855+0000] {processor.py:161} INFO - Started process (PID=2441) to work on /opt/airflow/dags/mydag.py
[2024-07-01T23:15:59.857+0000] {processor.py:830} INFO - Processing file /opt/airflow/dags/mydag.py for tasks to queue
[2024-07-01T23:15:59.860+0000] {logging_mixin.py:188} INFO - [2024-07-01T23:15:59.859+0000] {dagbag.py:538} INFO - Filling up the DagBag from /opt/airflow/dags/mydag.py
[2024-07-01T23:16:00.489+0000] {logging_mixin.py:188} INFO - postgress link postgresql://postgres:12345@192.168.176.1:5432/postgres
[2024-07-01T23:16:00.568+0000] {logging_mixin.py:188} INFO - [2024-07-01T23:16:00.551+0000] {dagbag.py:348} ERROR - Failed to import: /opt/airflow/dags/mydag.py
Traceback (most recent call last):
  File "/home/airflow/.local/lib/python3.8/site-packages/airflow/models/dagbag.py", line 344, in parse
    loader.exec_module(new_module)
  File "<frozen importlib._bootstrap_external>", line 843, in exec_module
  File "<frozen importlib._bootstrap>", line 219, in _call_with_frames_removed
  File "/opt/airflow/dags/mydag.py", line 28, in <module>
    python_callable=data_etl.run(),
  File "/opt/airflow/dags/Scripts/data_etl.py", line 61, in run
    with WarehouseConnection(get_warehouse_creds()).managed_cursor() as curr:
  File "/usr/local/lib/python3.8/contextlib.py", line 113, in __enter__
    return next(self.gen)
  File "/opt/airflow/dags/Scripts/db.py", line 26, in managed_cursor
    self.conn = psycopg2.connect(self.conn_url)
  File "/home/airflow/.local/lib/python3.8/site-packages/psycopg2/__init__.py", line 122, in connect
    conn = _connect(dsn, connection_factory=connection_factory, **kwasync)
psycopg2.OperationalError: connection to server at "192.168.176.1", port 5432 failed: FATAL:  no pg_hba.conf entry for host "192.168.176.1", user "postgres", database "postgres", no encryption
[2024-07-01T23:16:00.571+0000] {processor.py:842} WARNING - No viable dags retrieved from /opt/airflow/dags/mydag.py
[2024-07-01T23:16:00.603+0000] {processor.py:183} INFO - Processing /opt/airflow/dags/mydag.py took 0.754 seconds
[2024-07-01T23:16:30.753+0000] {processor.py:161} INFO - Started process (PID=2448) to work on /opt/airflow/dags/mydag.py
[2024-07-01T23:16:30.755+0000] {processor.py:830} INFO - Processing file /opt/airflow/dags/mydag.py for tasks to queue
[2024-07-01T23:16:30.767+0000] {logging_mixin.py:188} INFO - [2024-07-01T23:16:30.766+0000] {dagbag.py:538} INFO - Filling up the DagBag from /opt/airflow/dags/mydag.py
[2024-07-01T23:16:31.496+0000] {logging_mixin.py:188} INFO - postgress link postgresql://postgres:12345@192.168.176.1:5432/postgres
[2024-07-01T23:16:31.615+0000] {logging_mixin.py:188} INFO - [2024-07-01T23:16:31.590+0000] {dagbag.py:348} ERROR - Failed to import: /opt/airflow/dags/mydag.py
Traceback (most recent call last):
  File "/home/airflow/.local/lib/python3.8/site-packages/airflow/models/dagbag.py", line 344, in parse
    loader.exec_module(new_module)
  File "<frozen importlib._bootstrap_external>", line 843, in exec_module
  File "<frozen importlib._bootstrap>", line 219, in _call_with_frames_removed
  File "/opt/airflow/dags/mydag.py", line 28, in <module>
    python_callable=data_etl.run(),
  File "/opt/airflow/dags/Scripts/data_etl.py", line 61, in run
    with WarehouseConnection(get_warehouse_creds()).managed_cursor() as curr:
  File "/usr/local/lib/python3.8/contextlib.py", line 113, in __enter__
    return next(self.gen)
  File "/opt/airflow/dags/Scripts/db.py", line 26, in managed_cursor
    self.conn = psycopg2.connect(self.conn_url)
  File "/home/airflow/.local/lib/python3.8/site-packages/psycopg2/__init__.py", line 122, in connect
    conn = _connect(dsn, connection_factory=connection_factory, **kwasync)
psycopg2.OperationalError: connection to server at "192.168.176.1", port 5432 failed: FATAL:  no pg_hba.conf entry for host "192.168.176.1", user "postgres", database "postgres", no encryption
[2024-07-01T23:16:31.620+0000] {processor.py:842} WARNING - No viable dags retrieved from /opt/airflow/dags/mydag.py
[2024-07-01T23:16:31.676+0000] {processor.py:183} INFO - Processing /opt/airflow/dags/mydag.py took 0.932 seconds
[2024-07-01T23:17:02.024+0000] {processor.py:161} INFO - Started process (PID=2455) to work on /opt/airflow/dags/mydag.py
[2024-07-01T23:17:02.026+0000] {processor.py:830} INFO - Processing file /opt/airflow/dags/mydag.py for tasks to queue
[2024-07-01T23:17:02.028+0000] {logging_mixin.py:188} INFO - [2024-07-01T23:17:02.028+0000] {dagbag.py:538} INFO - Filling up the DagBag from /opt/airflow/dags/mydag.py
[2024-07-01T23:17:02.638+0000] {logging_mixin.py:188} INFO - postgress link postgresql://postgres:12345@192.168.176.1:5432/postgres
[2024-07-01T23:17:02.734+0000] {logging_mixin.py:188} INFO - [2024-07-01T23:17:02.710+0000] {dagbag.py:348} ERROR - Failed to import: /opt/airflow/dags/mydag.py
Traceback (most recent call last):
  File "/home/airflow/.local/lib/python3.8/site-packages/airflow/models/dagbag.py", line 344, in parse
    loader.exec_module(new_module)
  File "<frozen importlib._bootstrap_external>", line 843, in exec_module
  File "<frozen importlib._bootstrap>", line 219, in _call_with_frames_removed
  File "/opt/airflow/dags/mydag.py", line 28, in <module>
    python_callable=data_etl.run(),
  File "/opt/airflow/dags/Scripts/data_etl.py", line 61, in run
    with WarehouseConnection(get_warehouse_creds()).managed_cursor() as curr:
  File "/usr/local/lib/python3.8/contextlib.py", line 113, in __enter__
    return next(self.gen)
  File "/opt/airflow/dags/Scripts/db.py", line 26, in managed_cursor
    self.conn = psycopg2.connect(self.conn_url)
  File "/home/airflow/.local/lib/python3.8/site-packages/psycopg2/__init__.py", line 122, in connect
    conn = _connect(dsn, connection_factory=connection_factory, **kwasync)
psycopg2.OperationalError: connection to server at "192.168.176.1", port 5432 failed: FATAL:  no pg_hba.conf entry for host "192.168.176.1", user "postgres", database "postgres", no encryption
[2024-07-01T23:17:02.737+0000] {processor.py:842} WARNING - No viable dags retrieved from /opt/airflow/dags/mydag.py
[2024-07-01T23:17:02.784+0000] {processor.py:183} INFO - Processing /opt/airflow/dags/mydag.py took 0.769 seconds
[2024-07-01T23:17:33.124+0000] {processor.py:161} INFO - Started process (PID=2462) to work on /opt/airflow/dags/mydag.py
[2024-07-01T23:17:33.126+0000] {processor.py:830} INFO - Processing file /opt/airflow/dags/mydag.py for tasks to queue
[2024-07-01T23:17:33.128+0000] {logging_mixin.py:188} INFO - [2024-07-01T23:17:33.128+0000] {dagbag.py:538} INFO - Filling up the DagBag from /opt/airflow/dags/mydag.py
[2024-07-01T23:17:33.749+0000] {logging_mixin.py:188} INFO - postgress link postgresql://postgres:12345@192.168.176.1:5432/postgres
[2024-07-01T23:17:33.860+0000] {logging_mixin.py:188} INFO - [2024-07-01T23:17:33.836+0000] {dagbag.py:348} ERROR - Failed to import: /opt/airflow/dags/mydag.py
Traceback (most recent call last):
  File "/home/airflow/.local/lib/python3.8/site-packages/airflow/models/dagbag.py", line 344, in parse
    loader.exec_module(new_module)
  File "<frozen importlib._bootstrap_external>", line 843, in exec_module
  File "<frozen importlib._bootstrap>", line 219, in _call_with_frames_removed
  File "/opt/airflow/dags/mydag.py", line 28, in <module>
    python_callable=data_etl.run(),
  File "/opt/airflow/dags/Scripts/data_etl.py", line 61, in run
    with WarehouseConnection(get_warehouse_creds()).managed_cursor() as curr:
  File "/usr/local/lib/python3.8/contextlib.py", line 113, in __enter__
    return next(self.gen)
  File "/opt/airflow/dags/Scripts/db.py", line 26, in managed_cursor
    self.conn = psycopg2.connect(self.conn_url)
  File "/home/airflow/.local/lib/python3.8/site-packages/psycopg2/__init__.py", line 122, in connect
    conn = _connect(dsn, connection_factory=connection_factory, **kwasync)
psycopg2.OperationalError: connection to server at "192.168.176.1", port 5432 failed: FATAL:  no pg_hba.conf entry for host "192.168.176.1", user "postgres", database "postgres", no encryption
[2024-07-01T23:17:33.862+0000] {processor.py:842} WARNING - No viable dags retrieved from /opt/airflow/dags/mydag.py
[2024-07-01T23:17:33.898+0000] {processor.py:183} INFO - Processing /opt/airflow/dags/mydag.py took 0.781 seconds
[2024-07-01T23:18:04.186+0000] {processor.py:161} INFO - Started process (PID=2469) to work on /opt/airflow/dags/mydag.py
[2024-07-01T23:18:04.188+0000] {processor.py:830} INFO - Processing file /opt/airflow/dags/mydag.py for tasks to queue
[2024-07-01T23:18:04.191+0000] {logging_mixin.py:188} INFO - [2024-07-01T23:18:04.190+0000] {dagbag.py:538} INFO - Filling up the DagBag from /opt/airflow/dags/mydag.py
[2024-07-01T23:18:04.632+0000] {logging_mixin.py:188} INFO - postgress link postgresql://postgres:12345@192.168.176.1:5432/postgres
[2024-07-01T23:18:04.718+0000] {logging_mixin.py:188} INFO - [2024-07-01T23:18:04.694+0000] {dagbag.py:348} ERROR - Failed to import: /opt/airflow/dags/mydag.py
Traceback (most recent call last):
  File "/home/airflow/.local/lib/python3.8/site-packages/airflow/models/dagbag.py", line 344, in parse
    loader.exec_module(new_module)
  File "<frozen importlib._bootstrap_external>", line 843, in exec_module
  File "<frozen importlib._bootstrap>", line 219, in _call_with_frames_removed
  File "/opt/airflow/dags/mydag.py", line 28, in <module>
    python_callable=data_etl.run(),
  File "/opt/airflow/dags/Scripts/data_etl.py", line 61, in run
    with WarehouseConnection(get_warehouse_creds()).managed_cursor() as curr:
  File "/usr/local/lib/python3.8/contextlib.py", line 113, in __enter__
    return next(self.gen)
  File "/opt/airflow/dags/Scripts/db.py", line 26, in managed_cursor
    self.conn = psycopg2.connect(self.conn_url)
  File "/home/airflow/.local/lib/python3.8/site-packages/psycopg2/__init__.py", line 122, in connect
    conn = _connect(dsn, connection_factory=connection_factory, **kwasync)
psycopg2.OperationalError: connection to server at "192.168.176.1", port 5432 failed: FATAL:  no pg_hba.conf entry for host "192.168.176.1", user "postgres", database "postgres", no encryption
[2024-07-01T23:18:04.721+0000] {processor.py:842} WARNING - No viable dags retrieved from /opt/airflow/dags/mydag.py
[2024-07-01T23:18:04.754+0000] {processor.py:183} INFO - Processing /opt/airflow/dags/mydag.py took 0.574 seconds
[2024-07-01T23:18:35.062+0000] {processor.py:161} INFO - Started process (PID=2476) to work on /opt/airflow/dags/mydag.py
[2024-07-01T23:18:35.064+0000] {processor.py:830} INFO - Processing file /opt/airflow/dags/mydag.py for tasks to queue
[2024-07-01T23:18:35.066+0000] {logging_mixin.py:188} INFO - [2024-07-01T23:18:35.066+0000] {dagbag.py:538} INFO - Filling up the DagBag from /opt/airflow/dags/mydag.py
[2024-07-01T23:18:35.684+0000] {logging_mixin.py:188} INFO - postgress link postgresql://postgres:12345@192.168.176.1:5432/postgres
[2024-07-01T23:18:35.775+0000] {logging_mixin.py:188} INFO - [2024-07-01T23:18:35.748+0000] {dagbag.py:348} ERROR - Failed to import: /opt/airflow/dags/mydag.py
Traceback (most recent call last):
  File "/home/airflow/.local/lib/python3.8/site-packages/airflow/models/dagbag.py", line 344, in parse
    loader.exec_module(new_module)
  File "<frozen importlib._bootstrap_external>", line 843, in exec_module
  File "<frozen importlib._bootstrap>", line 219, in _call_with_frames_removed
  File "/opt/airflow/dags/mydag.py", line 28, in <module>
    python_callable=data_etl.run(),
  File "/opt/airflow/dags/Scripts/data_etl.py", line 61, in run
    with WarehouseConnection(get_warehouse_creds()).managed_cursor() as curr:
  File "/usr/local/lib/python3.8/contextlib.py", line 113, in __enter__
    return next(self.gen)
  File "/opt/airflow/dags/Scripts/db.py", line 26, in managed_cursor
    self.conn = psycopg2.connect(self.conn_url)
  File "/home/airflow/.local/lib/python3.8/site-packages/psycopg2/__init__.py", line 122, in connect
    conn = _connect(dsn, connection_factory=connection_factory, **kwasync)
psycopg2.OperationalError: connection to server at "192.168.176.1", port 5432 failed: FATAL:  no pg_hba.conf entry for host "192.168.176.1", user "postgres", database "postgres", no encryption
[2024-07-01T23:18:35.779+0000] {processor.py:842} WARNING - No viable dags retrieved from /opt/airflow/dags/mydag.py
[2024-07-01T23:18:35.821+0000] {processor.py:183} INFO - Processing /opt/airflow/dags/mydag.py took 0.766 seconds
[2024-07-01T23:19:06.143+0000] {processor.py:161} INFO - Started process (PID=2483) to work on /opt/airflow/dags/mydag.py
[2024-07-01T23:19:06.146+0000] {processor.py:830} INFO - Processing file /opt/airflow/dags/mydag.py for tasks to queue
[2024-07-01T23:19:06.148+0000] {logging_mixin.py:188} INFO - [2024-07-01T23:19:06.147+0000] {dagbag.py:538} INFO - Filling up the DagBag from /opt/airflow/dags/mydag.py
[2024-07-01T23:19:06.767+0000] {logging_mixin.py:188} INFO - postgress link postgresql://postgres:12345@192.168.176.1:5432/postgres
[2024-07-01T23:19:06.854+0000] {logging_mixin.py:188} INFO - [2024-07-01T23:19:06.832+0000] {dagbag.py:348} ERROR - Failed to import: /opt/airflow/dags/mydag.py
Traceback (most recent call last):
  File "/home/airflow/.local/lib/python3.8/site-packages/airflow/models/dagbag.py", line 344, in parse
    loader.exec_module(new_module)
  File "<frozen importlib._bootstrap_external>", line 843, in exec_module
  File "<frozen importlib._bootstrap>", line 219, in _call_with_frames_removed
  File "/opt/airflow/dags/mydag.py", line 28, in <module>
    python_callable=data_etl.run(),
  File "/opt/airflow/dags/Scripts/data_etl.py", line 61, in run
    with WarehouseConnection(get_warehouse_creds()).managed_cursor() as curr:
  File "/usr/local/lib/python3.8/contextlib.py", line 113, in __enter__
    return next(self.gen)
  File "/opt/airflow/dags/Scripts/db.py", line 26, in managed_cursor
    self.conn = psycopg2.connect(self.conn_url)
  File "/home/airflow/.local/lib/python3.8/site-packages/psycopg2/__init__.py", line 122, in connect
    conn = _connect(dsn, connection_factory=connection_factory, **kwasync)
psycopg2.OperationalError: connection to server at "192.168.176.1", port 5432 failed: FATAL:  no pg_hba.conf entry for host "192.168.176.1", user "postgres", database "postgres", no encryption
[2024-07-01T23:19:06.857+0000] {processor.py:842} WARNING - No viable dags retrieved from /opt/airflow/dags/mydag.py
[2024-07-01T23:19:06.896+0000] {processor.py:183} INFO - Processing /opt/airflow/dags/mydag.py took 0.760 seconds
[2024-07-01T23:19:37.006+0000] {processor.py:161} INFO - Started process (PID=2490) to work on /opt/airflow/dags/mydag.py
[2024-07-01T23:19:37.009+0000] {processor.py:830} INFO - Processing file /opt/airflow/dags/mydag.py for tasks to queue
[2024-07-01T23:19:37.018+0000] {logging_mixin.py:188} INFO - [2024-07-01T23:19:37.016+0000] {dagbag.py:538} INFO - Filling up the DagBag from /opt/airflow/dags/mydag.py
[2024-07-01T23:19:37.729+0000] {logging_mixin.py:188} INFO - postgress link postgresql://postgres:12345@192.168.176.1:5432/postgres
[2024-07-01T23:19:37.822+0000] {logging_mixin.py:188} INFO - [2024-07-01T23:19:37.802+0000] {dagbag.py:348} ERROR - Failed to import: /opt/airflow/dags/mydag.py
Traceback (most recent call last):
  File "/home/airflow/.local/lib/python3.8/site-packages/airflow/models/dagbag.py", line 344, in parse
    loader.exec_module(new_module)
  File "<frozen importlib._bootstrap_external>", line 843, in exec_module
  File "<frozen importlib._bootstrap>", line 219, in _call_with_frames_removed
  File "/opt/airflow/dags/mydag.py", line 28, in <module>
    python_callable=data_etl.run(),
  File "/opt/airflow/dags/Scripts/data_etl.py", line 61, in run
    with WarehouseConnection(get_warehouse_creds()).managed_cursor() as curr:
  File "/usr/local/lib/python3.8/contextlib.py", line 113, in __enter__
    return next(self.gen)
  File "/opt/airflow/dags/Scripts/db.py", line 26, in managed_cursor
    self.conn = psycopg2.connect(self.conn_url)
  File "/home/airflow/.local/lib/python3.8/site-packages/psycopg2/__init__.py", line 122, in connect
    conn = _connect(dsn, connection_factory=connection_factory, **kwasync)
psycopg2.OperationalError: connection to server at "192.168.176.1", port 5432 failed: FATAL:  no pg_hba.conf entry for host "192.168.176.1", user "postgres", database "postgres", no encryption
[2024-07-01T23:19:37.827+0000] {processor.py:842} WARNING - No viable dags retrieved from /opt/airflow/dags/mydag.py
[2024-07-01T23:19:37.867+0000] {processor.py:183} INFO - Processing /opt/airflow/dags/mydag.py took 0.869 seconds
[2024-07-01T23:20:08.209+0000] {processor.py:161} INFO - Started process (PID=2497) to work on /opt/airflow/dags/mydag.py
[2024-07-01T23:20:08.211+0000] {processor.py:830} INFO - Processing file /opt/airflow/dags/mydag.py for tasks to queue
[2024-07-01T23:20:08.213+0000] {logging_mixin.py:188} INFO - [2024-07-01T23:20:08.212+0000] {dagbag.py:538} INFO - Filling up the DagBag from /opt/airflow/dags/mydag.py
[2024-07-01T23:20:08.902+0000] {logging_mixin.py:188} INFO - postgress link postgresql://postgres:12345@192.168.176.1:5432/postgres
[2024-07-01T23:20:08.987+0000] {logging_mixin.py:188} INFO - [2024-07-01T23:20:08.966+0000] {dagbag.py:348} ERROR - Failed to import: /opt/airflow/dags/mydag.py
Traceback (most recent call last):
  File "/home/airflow/.local/lib/python3.8/site-packages/airflow/models/dagbag.py", line 344, in parse
    loader.exec_module(new_module)
  File "<frozen importlib._bootstrap_external>", line 843, in exec_module
  File "<frozen importlib._bootstrap>", line 219, in _call_with_frames_removed
  File "/opt/airflow/dags/mydag.py", line 28, in <module>
    python_callable=data_etl.run(),
  File "/opt/airflow/dags/Scripts/data_etl.py", line 61, in run
    with WarehouseConnection(get_warehouse_creds()).managed_cursor() as curr:
  File "/usr/local/lib/python3.8/contextlib.py", line 113, in __enter__
    return next(self.gen)
  File "/opt/airflow/dags/Scripts/db.py", line 26, in managed_cursor
    self.conn = psycopg2.connect(self.conn_url)
  File "/home/airflow/.local/lib/python3.8/site-packages/psycopg2/__init__.py", line 122, in connect
    conn = _connect(dsn, connection_factory=connection_factory, **kwasync)
psycopg2.OperationalError: connection to server at "192.168.176.1", port 5432 failed: FATAL:  no pg_hba.conf entry for host "192.168.176.1", user "postgres", database "postgres", no encryption
[2024-07-01T23:20:08.990+0000] {processor.py:842} WARNING - No viable dags retrieved from /opt/airflow/dags/mydag.py
[2024-07-01T23:20:09.029+0000] {processor.py:183} INFO - Processing /opt/airflow/dags/mydag.py took 0.829 seconds
[2024-07-01T23:20:39.412+0000] {processor.py:161} INFO - Started process (PID=2504) to work on /opt/airflow/dags/mydag.py
[2024-07-01T23:20:39.414+0000] {processor.py:830} INFO - Processing file /opt/airflow/dags/mydag.py for tasks to queue
[2024-07-01T23:20:39.417+0000] {logging_mixin.py:188} INFO - [2024-07-01T23:20:39.417+0000] {dagbag.py:538} INFO - Filling up the DagBag from /opt/airflow/dags/mydag.py
[2024-07-01T23:20:40.019+0000] {logging_mixin.py:188} INFO - postgress link postgresql://postgres:12345@192.168.176.1:5432/postgres
[2024-07-01T23:20:40.107+0000] {logging_mixin.py:188} INFO - [2024-07-01T23:20:40.090+0000] {dagbag.py:348} ERROR - Failed to import: /opt/airflow/dags/mydag.py
Traceback (most recent call last):
  File "/home/airflow/.local/lib/python3.8/site-packages/airflow/models/dagbag.py", line 344, in parse
    loader.exec_module(new_module)
  File "<frozen importlib._bootstrap_external>", line 843, in exec_module
  File "<frozen importlib._bootstrap>", line 219, in _call_with_frames_removed
  File "/opt/airflow/dags/mydag.py", line 28, in <module>
    python_callable=data_etl.run(),
  File "/opt/airflow/dags/Scripts/data_etl.py", line 61, in run
    with WarehouseConnection(get_warehouse_creds()).managed_cursor() as curr:
  File "/usr/local/lib/python3.8/contextlib.py", line 113, in __enter__
    return next(self.gen)
  File "/opt/airflow/dags/Scripts/db.py", line 26, in managed_cursor
    self.conn = psycopg2.connect(self.conn_url)
  File "/home/airflow/.local/lib/python3.8/site-packages/psycopg2/__init__.py", line 122, in connect
    conn = _connect(dsn, connection_factory=connection_factory, **kwasync)
psycopg2.OperationalError: connection to server at "192.168.176.1", port 5432 failed: FATAL:  no pg_hba.conf entry for host "192.168.176.1", user "postgres", database "postgres", no encryption
[2024-07-01T23:20:40.110+0000] {processor.py:842} WARNING - No viable dags retrieved from /opt/airflow/dags/mydag.py
[2024-07-01T23:20:40.145+0000] {processor.py:183} INFO - Processing /opt/airflow/dags/mydag.py took 0.741 seconds
[2024-07-01T23:21:10.492+0000] {processor.py:161} INFO - Started process (PID=2511) to work on /opt/airflow/dags/mydag.py
[2024-07-01T23:21:10.494+0000] {processor.py:830} INFO - Processing file /opt/airflow/dags/mydag.py for tasks to queue
[2024-07-01T23:21:10.496+0000] {logging_mixin.py:188} INFO - [2024-07-01T23:21:10.496+0000] {dagbag.py:538} INFO - Filling up the DagBag from /opt/airflow/dags/mydag.py
[2024-07-01T23:21:10.922+0000] {logging_mixin.py:188} INFO - postgress link postgresql://postgres:12345@192.168.176.1:5432/postgres
[2024-07-01T23:21:11.003+0000] {logging_mixin.py:188} INFO - [2024-07-01T23:21:10.983+0000] {dagbag.py:348} ERROR - Failed to import: /opt/airflow/dags/mydag.py
Traceback (most recent call last):
  File "/home/airflow/.local/lib/python3.8/site-packages/airflow/models/dagbag.py", line 344, in parse
    loader.exec_module(new_module)
  File "<frozen importlib._bootstrap_external>", line 843, in exec_module
  File "<frozen importlib._bootstrap>", line 219, in _call_with_frames_removed
  File "/opt/airflow/dags/mydag.py", line 28, in <module>
    python_callable=data_etl.run(),
  File "/opt/airflow/dags/Scripts/data_etl.py", line 61, in run
    with WarehouseConnection(get_warehouse_creds()).managed_cursor() as curr:
  File "/usr/local/lib/python3.8/contextlib.py", line 113, in __enter__
    return next(self.gen)
  File "/opt/airflow/dags/Scripts/db.py", line 26, in managed_cursor
    self.conn = psycopg2.connect(self.conn_url)
  File "/home/airflow/.local/lib/python3.8/site-packages/psycopg2/__init__.py", line 122, in connect
    conn = _connect(dsn, connection_factory=connection_factory, **kwasync)
psycopg2.OperationalError: connection to server at "192.168.176.1", port 5432 failed: FATAL:  no pg_hba.conf entry for host "192.168.176.1", user "postgres", database "postgres", no encryption
[2024-07-01T23:21:11.007+0000] {processor.py:842} WARNING - No viable dags retrieved from /opt/airflow/dags/mydag.py
[2024-07-01T23:21:11.048+0000] {processor.py:183} INFO - Processing /opt/airflow/dags/mydag.py took 0.564 seconds
[2024-07-01T23:21:41.359+0000] {processor.py:161} INFO - Started process (PID=2518) to work on /opt/airflow/dags/mydag.py
[2024-07-01T23:21:41.361+0000] {processor.py:830} INFO - Processing file /opt/airflow/dags/mydag.py for tasks to queue
[2024-07-01T23:21:41.363+0000] {logging_mixin.py:188} INFO - [2024-07-01T23:21:41.363+0000] {dagbag.py:538} INFO - Filling up the DagBag from /opt/airflow/dags/mydag.py
[2024-07-01T23:21:41.965+0000] {logging_mixin.py:188} INFO - postgress link postgresql://postgres:12345@192.168.176.1:5432/postgres
[2024-07-01T23:21:42.059+0000] {logging_mixin.py:188} INFO - [2024-07-01T23:21:42.035+0000] {dagbag.py:348} ERROR - Failed to import: /opt/airflow/dags/mydag.py
Traceback (most recent call last):
  File "/home/airflow/.local/lib/python3.8/site-packages/airflow/models/dagbag.py", line 344, in parse
    loader.exec_module(new_module)
  File "<frozen importlib._bootstrap_external>", line 843, in exec_module
  File "<frozen importlib._bootstrap>", line 219, in _call_with_frames_removed
  File "/opt/airflow/dags/mydag.py", line 28, in <module>
    python_callable=data_etl.run(),
  File "/opt/airflow/dags/Scripts/data_etl.py", line 61, in run
    with WarehouseConnection(get_warehouse_creds()).managed_cursor() as curr:
  File "/usr/local/lib/python3.8/contextlib.py", line 113, in __enter__
    return next(self.gen)
  File "/opt/airflow/dags/Scripts/db.py", line 26, in managed_cursor
    self.conn = psycopg2.connect(self.conn_url)
  File "/home/airflow/.local/lib/python3.8/site-packages/psycopg2/__init__.py", line 122, in connect
    conn = _connect(dsn, connection_factory=connection_factory, **kwasync)
psycopg2.OperationalError: connection to server at "192.168.176.1", port 5432 failed: FATAL:  no pg_hba.conf entry for host "192.168.176.1", user "postgres", database "postgres", no encryption
[2024-07-01T23:21:42.063+0000] {processor.py:842} WARNING - No viable dags retrieved from /opt/airflow/dags/mydag.py
[2024-07-01T23:21:42.098+0000] {processor.py:183} INFO - Processing /opt/airflow/dags/mydag.py took 0.745 seconds
[2024-07-01T23:22:12.652+0000] {processor.py:161} INFO - Started process (PID=2525) to work on /opt/airflow/dags/mydag.py
[2024-07-01T23:22:12.656+0000] {processor.py:830} INFO - Processing file /opt/airflow/dags/mydag.py for tasks to queue
[2024-07-01T23:22:12.659+0000] {logging_mixin.py:188} INFO - [2024-07-01T23:22:12.658+0000] {dagbag.py:538} INFO - Filling up the DagBag from /opt/airflow/dags/mydag.py
[2024-07-01T23:22:13.283+0000] {logging_mixin.py:188} INFO - postgress link postgresql://postgres:12345@192.168.176.1:5432/postgres
[2024-07-01T23:22:13.364+0000] {logging_mixin.py:188} INFO - [2024-07-01T23:22:13.344+0000] {dagbag.py:348} ERROR - Failed to import: /opt/airflow/dags/mydag.py
Traceback (most recent call last):
  File "/home/airflow/.local/lib/python3.8/site-packages/airflow/models/dagbag.py", line 344, in parse
    loader.exec_module(new_module)
  File "<frozen importlib._bootstrap_external>", line 843, in exec_module
  File "<frozen importlib._bootstrap>", line 219, in _call_with_frames_removed
  File "/opt/airflow/dags/mydag.py", line 28, in <module>
    python_callable=data_etl.run(),
  File "/opt/airflow/dags/Scripts/data_etl.py", line 61, in run
    with WarehouseConnection(get_warehouse_creds()).managed_cursor() as curr:
  File "/usr/local/lib/python3.8/contextlib.py", line 113, in __enter__
    return next(self.gen)
  File "/opt/airflow/dags/Scripts/db.py", line 26, in managed_cursor
    self.conn = psycopg2.connect(self.conn_url)
  File "/home/airflow/.local/lib/python3.8/site-packages/psycopg2/__init__.py", line 122, in connect
    conn = _connect(dsn, connection_factory=connection_factory, **kwasync)
psycopg2.OperationalError: connection to server at "192.168.176.1", port 5432 failed: FATAL:  no pg_hba.conf entry for host "192.168.176.1", user "postgres", database "postgres", no encryption
[2024-07-01T23:22:13.367+0000] {processor.py:842} WARNING - No viable dags retrieved from /opt/airflow/dags/mydag.py
[2024-07-01T23:22:13.399+0000] {processor.py:183} INFO - Processing /opt/airflow/dags/mydag.py took 0.768 seconds
[2024-07-01T23:22:43.733+0000] {processor.py:161} INFO - Started process (PID=2532) to work on /opt/airflow/dags/mydag.py
[2024-07-01T23:22:43.735+0000] {processor.py:830} INFO - Processing file /opt/airflow/dags/mydag.py for tasks to queue
[2024-07-01T23:22:43.737+0000] {logging_mixin.py:188} INFO - [2024-07-01T23:22:43.736+0000] {dagbag.py:538} INFO - Filling up the DagBag from /opt/airflow/dags/mydag.py
[2024-07-01T23:22:44.351+0000] {logging_mixin.py:188} INFO - postgress link postgresql://postgres:12345@192.168.176.1:5432/postgres
[2024-07-01T23:22:44.432+0000] {logging_mixin.py:188} INFO - [2024-07-01T23:22:44.411+0000] {dagbag.py:348} ERROR - Failed to import: /opt/airflow/dags/mydag.py
Traceback (most recent call last):
  File "/home/airflow/.local/lib/python3.8/site-packages/airflow/models/dagbag.py", line 344, in parse
    loader.exec_module(new_module)
  File "<frozen importlib._bootstrap_external>", line 843, in exec_module
  File "<frozen importlib._bootstrap>", line 219, in _call_with_frames_removed
  File "/opt/airflow/dags/mydag.py", line 28, in <module>
    python_callable=data_etl.run(),
  File "/opt/airflow/dags/Scripts/data_etl.py", line 61, in run
    with WarehouseConnection(get_warehouse_creds()).managed_cursor() as curr:
  File "/usr/local/lib/python3.8/contextlib.py", line 113, in __enter__
    return next(self.gen)
  File "/opt/airflow/dags/Scripts/db.py", line 26, in managed_cursor
    self.conn = psycopg2.connect(self.conn_url)
  File "/home/airflow/.local/lib/python3.8/site-packages/psycopg2/__init__.py", line 122, in connect
    conn = _connect(dsn, connection_factory=connection_factory, **kwasync)
psycopg2.OperationalError: connection to server at "192.168.176.1", port 5432 failed: FATAL:  no pg_hba.conf entry for host "192.168.176.1", user "postgres", database "postgres", no encryption
[2024-07-01T23:22:44.434+0000] {processor.py:842} WARNING - No viable dags retrieved from /opt/airflow/dags/mydag.py
[2024-07-01T23:22:44.466+0000] {processor.py:183} INFO - Processing /opt/airflow/dags/mydag.py took 0.740 seconds
[2024-07-01T23:23:14.615+0000] {processor.py:161} INFO - Started process (PID=2539) to work on /opt/airflow/dags/mydag.py
[2024-07-01T23:23:14.617+0000] {processor.py:830} INFO - Processing file /opt/airflow/dags/mydag.py for tasks to queue
[2024-07-01T23:23:14.619+0000] {logging_mixin.py:188} INFO - [2024-07-01T23:23:14.619+0000] {dagbag.py:538} INFO - Filling up the DagBag from /opt/airflow/dags/mydag.py
[2024-07-01T23:23:15.039+0000] {logging_mixin.py:188} INFO - postgress link postgresql://postgres:12345@192.168.176.1:5432/postgres
[2024-07-01T23:23:15.122+0000] {logging_mixin.py:188} INFO - [2024-07-01T23:23:15.100+0000] {dagbag.py:348} ERROR - Failed to import: /opt/airflow/dags/mydag.py
Traceback (most recent call last):
  File "/home/airflow/.local/lib/python3.8/site-packages/airflow/models/dagbag.py", line 344, in parse
    loader.exec_module(new_module)
  File "<frozen importlib._bootstrap_external>", line 843, in exec_module
  File "<frozen importlib._bootstrap>", line 219, in _call_with_frames_removed
  File "/opt/airflow/dags/mydag.py", line 28, in <module>
    python_callable=data_etl.run(),
  File "/opt/airflow/dags/Scripts/data_etl.py", line 61, in run
    with WarehouseConnection(get_warehouse_creds()).managed_cursor() as curr:
  File "/usr/local/lib/python3.8/contextlib.py", line 113, in __enter__
    return next(self.gen)
  File "/opt/airflow/dags/Scripts/db.py", line 26, in managed_cursor
    self.conn = psycopg2.connect(self.conn_url)
  File "/home/airflow/.local/lib/python3.8/site-packages/psycopg2/__init__.py", line 122, in connect
    conn = _connect(dsn, connection_factory=connection_factory, **kwasync)
psycopg2.OperationalError: connection to server at "192.168.176.1", port 5432 failed: FATAL:  no pg_hba.conf entry for host "192.168.176.1", user "postgres", database "postgres", no encryption
[2024-07-01T23:23:15.125+0000] {processor.py:842} WARNING - No viable dags retrieved from /opt/airflow/dags/mydag.py
[2024-07-01T23:23:15.157+0000] {processor.py:183} INFO - Processing /opt/airflow/dags/mydag.py took 0.549 seconds
[2024-07-01T23:23:45.465+0000] {processor.py:161} INFO - Started process (PID=2546) to work on /opt/airflow/dags/mydag.py
[2024-07-01T23:23:45.467+0000] {processor.py:830} INFO - Processing file /opt/airflow/dags/mydag.py for tasks to queue
[2024-07-01T23:23:45.469+0000] {logging_mixin.py:188} INFO - [2024-07-01T23:23:45.468+0000] {dagbag.py:538} INFO - Filling up the DagBag from /opt/airflow/dags/mydag.py
[2024-07-01T23:23:46.062+0000] {logging_mixin.py:188} INFO - postgress link postgresql://postgres:12345@192.168.176.1:5432/postgres
[2024-07-01T23:23:46.148+0000] {logging_mixin.py:188} INFO - [2024-07-01T23:23:46.127+0000] {dagbag.py:348} ERROR - Failed to import: /opt/airflow/dags/mydag.py
Traceback (most recent call last):
  File "/home/airflow/.local/lib/python3.8/site-packages/airflow/models/dagbag.py", line 344, in parse
    loader.exec_module(new_module)
  File "<frozen importlib._bootstrap_external>", line 843, in exec_module
  File "<frozen importlib._bootstrap>", line 219, in _call_with_frames_removed
  File "/opt/airflow/dags/mydag.py", line 28, in <module>
    python_callable=data_etl.run(),
  File "/opt/airflow/dags/Scripts/data_etl.py", line 61, in run
    with WarehouseConnection(get_warehouse_creds()).managed_cursor() as curr:
  File "/usr/local/lib/python3.8/contextlib.py", line 113, in __enter__
    return next(self.gen)
  File "/opt/airflow/dags/Scripts/db.py", line 26, in managed_cursor
    self.conn = psycopg2.connect(self.conn_url)
  File "/home/airflow/.local/lib/python3.8/site-packages/psycopg2/__init__.py", line 122, in connect
    conn = _connect(dsn, connection_factory=connection_factory, **kwasync)
psycopg2.OperationalError: connection to server at "192.168.176.1", port 5432 failed: FATAL:  no pg_hba.conf entry for host "192.168.176.1", user "postgres", database "postgres", no encryption
[2024-07-01T23:23:46.150+0000] {processor.py:842} WARNING - No viable dags retrieved from /opt/airflow/dags/mydag.py
[2024-07-01T23:23:46.182+0000] {processor.py:183} INFO - Processing /opt/airflow/dags/mydag.py took 0.724 seconds
[2024-07-01T23:24:16.329+0000] {processor.py:161} INFO - Started process (PID=2553) to work on /opt/airflow/dags/mydag.py
[2024-07-01T23:24:16.331+0000] {processor.py:830} INFO - Processing file /opt/airflow/dags/mydag.py for tasks to queue
[2024-07-01T23:24:16.333+0000] {logging_mixin.py:188} INFO - [2024-07-01T23:24:16.333+0000] {dagbag.py:538} INFO - Filling up the DagBag from /opt/airflow/dags/mydag.py
[2024-07-01T23:24:16.931+0000] {logging_mixin.py:188} INFO - postgress link postgresql://postgres:12345@192.168.176.1:5432/postgres
[2024-07-01T23:24:17.014+0000] {logging_mixin.py:188} INFO - [2024-07-01T23:24:16.993+0000] {dagbag.py:348} ERROR - Failed to import: /opt/airflow/dags/mydag.py
Traceback (most recent call last):
  File "/home/airflow/.local/lib/python3.8/site-packages/airflow/models/dagbag.py", line 344, in parse
    loader.exec_module(new_module)
  File "<frozen importlib._bootstrap_external>", line 843, in exec_module
  File "<frozen importlib._bootstrap>", line 219, in _call_with_frames_removed
  File "/opt/airflow/dags/mydag.py", line 28, in <module>
    python_callable=data_etl.run(),
  File "/opt/airflow/dags/Scripts/data_etl.py", line 61, in run
    with WarehouseConnection(get_warehouse_creds()).managed_cursor() as curr:
  File "/usr/local/lib/python3.8/contextlib.py", line 113, in __enter__
    return next(self.gen)
  File "/opt/airflow/dags/Scripts/db.py", line 26, in managed_cursor
    self.conn = psycopg2.connect(self.conn_url)
  File "/home/airflow/.local/lib/python3.8/site-packages/psycopg2/__init__.py", line 122, in connect
    conn = _connect(dsn, connection_factory=connection_factory, **kwasync)
psycopg2.OperationalError: connection to server at "192.168.176.1", port 5432 failed: FATAL:  no pg_hba.conf entry for host "192.168.176.1", user "postgres", database "postgres", no encryption
[2024-07-01T23:24:17.017+0000] {processor.py:842} WARNING - No viable dags retrieved from /opt/airflow/dags/mydag.py
[2024-07-01T23:24:17.049+0000] {processor.py:183} INFO - Processing /opt/airflow/dags/mydag.py took 0.726 seconds
[2024-07-01T23:24:47.390+0000] {processor.py:161} INFO - Started process (PID=2560) to work on /opt/airflow/dags/mydag.py
[2024-07-01T23:24:47.396+0000] {processor.py:830} INFO - Processing file /opt/airflow/dags/mydag.py for tasks to queue
[2024-07-01T23:24:47.402+0000] {logging_mixin.py:188} INFO - [2024-07-01T23:24:47.401+0000] {dagbag.py:538} INFO - Filling up the DagBag from /opt/airflow/dags/mydag.py
[2024-07-01T23:24:48.124+0000] {logging_mixin.py:188} INFO - postgress link postgresql://postgres:12345@192.168.176.1:5432/postgres
[2024-07-01T23:24:48.232+0000] {logging_mixin.py:188} INFO - [2024-07-01T23:24:48.209+0000] {dagbag.py:348} ERROR - Failed to import: /opt/airflow/dags/mydag.py
Traceback (most recent call last):
  File "/home/airflow/.local/lib/python3.8/site-packages/airflow/models/dagbag.py", line 344, in parse
    loader.exec_module(new_module)
  File "<frozen importlib._bootstrap_external>", line 843, in exec_module
  File "<frozen importlib._bootstrap>", line 219, in _call_with_frames_removed
  File "/opt/airflow/dags/mydag.py", line 28, in <module>
    python_callable=data_etl.run(),
  File "/opt/airflow/dags/Scripts/data_etl.py", line 61, in run
    with WarehouseConnection(get_warehouse_creds()).managed_cursor() as curr:
  File "/usr/local/lib/python3.8/contextlib.py", line 113, in __enter__
    return next(self.gen)
  File "/opt/airflow/dags/Scripts/db.py", line 26, in managed_cursor
    self.conn = psycopg2.connect(self.conn_url)
  File "/home/airflow/.local/lib/python3.8/site-packages/psycopg2/__init__.py", line 122, in connect
    conn = _connect(dsn, connection_factory=connection_factory, **kwasync)
psycopg2.OperationalError: connection to server at "192.168.176.1", port 5432 failed: FATAL:  no pg_hba.conf entry for host "192.168.176.1", user "postgres", database "postgres", no encryption
[2024-07-01T23:24:48.236+0000] {processor.py:842} WARNING - No viable dags retrieved from /opt/airflow/dags/mydag.py
[2024-07-01T23:24:48.280+0000] {processor.py:183} INFO - Processing /opt/airflow/dags/mydag.py took 0.908 seconds
[2024-07-01T23:25:18.614+0000] {processor.py:161} INFO - Started process (PID=2567) to work on /opt/airflow/dags/mydag.py
[2024-07-01T23:25:18.616+0000] {processor.py:830} INFO - Processing file /opt/airflow/dags/mydag.py for tasks to queue
[2024-07-01T23:25:18.619+0000] {logging_mixin.py:188} INFO - [2024-07-01T23:25:18.618+0000] {dagbag.py:538} INFO - Filling up the DagBag from /opt/airflow/dags/mydag.py
[2024-07-01T23:25:19.765+0000] {logging_mixin.py:188} INFO - postgress link postgresql://postgres:12345@192.168.176.1:5432/postgres
[2024-07-01T23:25:19.860+0000] {logging_mixin.py:188} INFO - [2024-07-01T23:25:19.836+0000] {dagbag.py:348} ERROR - Failed to import: /opt/airflow/dags/mydag.py
Traceback (most recent call last):
  File "/home/airflow/.local/lib/python3.8/site-packages/airflow/models/dagbag.py", line 344, in parse
    loader.exec_module(new_module)
  File "<frozen importlib._bootstrap_external>", line 843, in exec_module
  File "<frozen importlib._bootstrap>", line 219, in _call_with_frames_removed
  File "/opt/airflow/dags/mydag.py", line 28, in <module>
    python_callable=data_etl.run(),
  File "/opt/airflow/dags/Scripts/data_etl.py", line 61, in run
    with WarehouseConnection(get_warehouse_creds()).managed_cursor() as curr:
  File "/usr/local/lib/python3.8/contextlib.py", line 113, in __enter__
    return next(self.gen)
  File "/opt/airflow/dags/Scripts/db.py", line 26, in managed_cursor
    self.conn = psycopg2.connect(self.conn_url)
  File "/home/airflow/.local/lib/python3.8/site-packages/psycopg2/__init__.py", line 122, in connect
    conn = _connect(dsn, connection_factory=connection_factory, **kwasync)
psycopg2.OperationalError: connection to server at "192.168.176.1", port 5432 failed: FATAL:  no pg_hba.conf entry for host "192.168.176.1", user "postgres", database "postgres", no encryption
[2024-07-01T23:25:19.863+0000] {processor.py:842} WARNING - No viable dags retrieved from /opt/airflow/dags/mydag.py
[2024-07-01T23:25:19.895+0000] {processor.py:183} INFO - Processing /opt/airflow/dags/mydag.py took 1.288 seconds
[2024-07-01T23:25:50.203+0000] {processor.py:161} INFO - Started process (PID=2575) to work on /opt/airflow/dags/mydag.py
[2024-07-01T23:25:50.205+0000] {processor.py:830} INFO - Processing file /opt/airflow/dags/mydag.py for tasks to queue
[2024-07-01T23:25:50.208+0000] {logging_mixin.py:188} INFO - [2024-07-01T23:25:50.207+0000] {dagbag.py:538} INFO - Filling up the DagBag from /opt/airflow/dags/mydag.py
[2024-07-01T23:25:50.823+0000] {logging_mixin.py:188} INFO - postgress link postgresql://postgres:12345@192.168.176.1:5432/postgres
[2024-07-01T23:25:50.907+0000] {logging_mixin.py:188} INFO - [2024-07-01T23:25:50.884+0000] {dagbag.py:348} ERROR - Failed to import: /opt/airflow/dags/mydag.py
Traceback (most recent call last):
  File "/home/airflow/.local/lib/python3.8/site-packages/airflow/models/dagbag.py", line 344, in parse
    loader.exec_module(new_module)
  File "<frozen importlib._bootstrap_external>", line 843, in exec_module
  File "<frozen importlib._bootstrap>", line 219, in _call_with_frames_removed
  File "/opt/airflow/dags/mydag.py", line 28, in <module>
    python_callable=data_etl.run(),
  File "/opt/airflow/dags/Scripts/data_etl.py", line 61, in run
    with WarehouseConnection(get_warehouse_creds()).managed_cursor() as curr:
  File "/usr/local/lib/python3.8/contextlib.py", line 113, in __enter__
    return next(self.gen)
  File "/opt/airflow/dags/Scripts/db.py", line 26, in managed_cursor
    self.conn = psycopg2.connect(self.conn_url)
  File "/home/airflow/.local/lib/python3.8/site-packages/psycopg2/__init__.py", line 122, in connect
    conn = _connect(dsn, connection_factory=connection_factory, **kwasync)
psycopg2.OperationalError: connection to server at "192.168.176.1", port 5432 failed: FATAL:  no pg_hba.conf entry for host "192.168.176.1", user "postgres", database "postgres", no encryption
[2024-07-01T23:25:50.910+0000] {processor.py:842} WARNING - No viable dags retrieved from /opt/airflow/dags/mydag.py
[2024-07-01T23:25:50.954+0000] {processor.py:183} INFO - Processing /opt/airflow/dags/mydag.py took 0.757 seconds
[2024-07-01T23:26:21.208+0000] {processor.py:161} INFO - Started process (PID=2582) to work on /opt/airflow/dags/mydag.py
[2024-07-01T23:26:21.210+0000] {processor.py:830} INFO - Processing file /opt/airflow/dags/mydag.py for tasks to queue
[2024-07-01T23:26:21.212+0000] {logging_mixin.py:188} INFO - [2024-07-01T23:26:21.212+0000] {dagbag.py:538} INFO - Filling up the DagBag from /opt/airflow/dags/mydag.py
[2024-07-01T23:26:21.826+0000] {logging_mixin.py:188} INFO - postgress link postgresql://postgres:12345@192.168.176.1:5432/postgres
[2024-07-01T23:26:21.904+0000] {logging_mixin.py:188} INFO - [2024-07-01T23:26:21.884+0000] {dagbag.py:348} ERROR - Failed to import: /opt/airflow/dags/mydag.py
Traceback (most recent call last):
  File "/home/airflow/.local/lib/python3.8/site-packages/airflow/models/dagbag.py", line 344, in parse
    loader.exec_module(new_module)
  File "<frozen importlib._bootstrap_external>", line 843, in exec_module
  File "<frozen importlib._bootstrap>", line 219, in _call_with_frames_removed
  File "/opt/airflow/dags/mydag.py", line 28, in <module>
    python_callable=data_etl.run(),
  File "/opt/airflow/dags/Scripts/data_etl.py", line 61, in run
    with WarehouseConnection(get_warehouse_creds()).managed_cursor() as curr:
  File "/usr/local/lib/python3.8/contextlib.py", line 113, in __enter__
    return next(self.gen)
  File "/opt/airflow/dags/Scripts/db.py", line 26, in managed_cursor
    self.conn = psycopg2.connect(self.conn_url)
  File "/home/airflow/.local/lib/python3.8/site-packages/psycopg2/__init__.py", line 122, in connect
    conn = _connect(dsn, connection_factory=connection_factory, **kwasync)
psycopg2.OperationalError: connection to server at "192.168.176.1", port 5432 failed: FATAL:  no pg_hba.conf entry for host "192.168.176.1", user "postgres", database "postgres", no encryption
[2024-07-01T23:26:21.906+0000] {processor.py:842} WARNING - No viable dags retrieved from /opt/airflow/dags/mydag.py
[2024-07-01T23:26:21.938+0000] {processor.py:183} INFO - Processing /opt/airflow/dags/mydag.py took 0.736 seconds
[2024-07-01T23:26:52.270+0000] {processor.py:161} INFO - Started process (PID=2589) to work on /opt/airflow/dags/mydag.py
[2024-07-01T23:26:52.272+0000] {processor.py:830} INFO - Processing file /opt/airflow/dags/mydag.py for tasks to queue
[2024-07-01T23:26:52.274+0000] {logging_mixin.py:188} INFO - [2024-07-01T23:26:52.274+0000] {dagbag.py:538} INFO - Filling up the DagBag from /opt/airflow/dags/mydag.py
[2024-07-01T23:26:52.913+0000] {logging_mixin.py:188} INFO - postgress link postgresql://postgres:12345@192.168.176.1:5432/postgres
[2024-07-01T23:26:52.997+0000] {logging_mixin.py:188} INFO - [2024-07-01T23:26:52.982+0000] {dagbag.py:348} ERROR - Failed to import: /opt/airflow/dags/mydag.py
Traceback (most recent call last):
  File "/home/airflow/.local/lib/python3.8/site-packages/airflow/models/dagbag.py", line 344, in parse
    loader.exec_module(new_module)
  File "<frozen importlib._bootstrap_external>", line 843, in exec_module
  File "<frozen importlib._bootstrap>", line 219, in _call_with_frames_removed
  File "/opt/airflow/dags/mydag.py", line 28, in <module>
    python_callable=data_etl.run(),
  File "/opt/airflow/dags/Scripts/data_etl.py", line 61, in run
    with WarehouseConnection(get_warehouse_creds()).managed_cursor() as curr:
  File "/usr/local/lib/python3.8/contextlib.py", line 113, in __enter__
    return next(self.gen)
  File "/opt/airflow/dags/Scripts/db.py", line 26, in managed_cursor
    self.conn = psycopg2.connect(self.conn_url)
  File "/home/airflow/.local/lib/python3.8/site-packages/psycopg2/__init__.py", line 122, in connect
    conn = _connect(dsn, connection_factory=connection_factory, **kwasync)
psycopg2.OperationalError: connection to server at "192.168.176.1", port 5432 failed: FATAL:  no pg_hba.conf entry for host "192.168.176.1", user "postgres", database "postgres", no encryption
[2024-07-01T23:26:52.999+0000] {processor.py:842} WARNING - No viable dags retrieved from /opt/airflow/dags/mydag.py
[2024-07-01T23:26:53.036+0000] {processor.py:183} INFO - Processing /opt/airflow/dags/mydag.py took 0.774 seconds
[2024-07-01T23:27:23.368+0000] {processor.py:161} INFO - Started process (PID=2602) to work on /opt/airflow/dags/mydag.py
[2024-07-01T23:27:23.370+0000] {processor.py:830} INFO - Processing file /opt/airflow/dags/mydag.py for tasks to queue
[2024-07-01T23:27:23.371+0000] {logging_mixin.py:188} INFO - [2024-07-01T23:27:23.371+0000] {dagbag.py:538} INFO - Filling up the DagBag from /opt/airflow/dags/mydag.py
[2024-07-01T23:27:23.978+0000] {logging_mixin.py:188} INFO - postgress link postgresql://postgres:12345@192.168.176.1:5432/postgres
[2024-07-01T23:27:24.089+0000] {logging_mixin.py:188} INFO - [2024-07-01T23:27:24.065+0000] {dagbag.py:348} ERROR - Failed to import: /opt/airflow/dags/mydag.py
Traceback (most recent call last):
  File "/home/airflow/.local/lib/python3.8/site-packages/airflow/models/dagbag.py", line 344, in parse
    loader.exec_module(new_module)
  File "<frozen importlib._bootstrap_external>", line 843, in exec_module
  File "<frozen importlib._bootstrap>", line 219, in _call_with_frames_removed
  File "/opt/airflow/dags/mydag.py", line 28, in <module>
    python_callable=data_etl.run(),
  File "/opt/airflow/dags/Scripts/data_etl.py", line 61, in run
    with WarehouseConnection(get_warehouse_creds()).managed_cursor() as curr:
  File "/usr/local/lib/python3.8/contextlib.py", line 113, in __enter__
    return next(self.gen)
  File "/opt/airflow/dags/Scripts/db.py", line 26, in managed_cursor
    self.conn = psycopg2.connect(self.conn_url)
  File "/home/airflow/.local/lib/python3.8/site-packages/psycopg2/__init__.py", line 122, in connect
    conn = _connect(dsn, connection_factory=connection_factory, **kwasync)
psycopg2.OperationalError: connection to server at "192.168.176.1", port 5432 failed: FATAL:  no pg_hba.conf entry for host "192.168.176.1", user "postgres", database "postgres", no encryption
[2024-07-01T23:27:24.092+0000] {processor.py:842} WARNING - No viable dags retrieved from /opt/airflow/dags/mydag.py
[2024-07-01T23:27:24.140+0000] {processor.py:183} INFO - Processing /opt/airflow/dags/mydag.py took 0.781 seconds
[2024-07-01T23:27:54.294+0000] {processor.py:161} INFO - Started process (PID=2609) to work on /opt/airflow/dags/mydag.py
[2024-07-01T23:27:54.296+0000] {processor.py:830} INFO - Processing file /opt/airflow/dags/mydag.py for tasks to queue
[2024-07-01T23:27:54.298+0000] {logging_mixin.py:188} INFO - [2024-07-01T23:27:54.298+0000] {dagbag.py:538} INFO - Filling up the DagBag from /opt/airflow/dags/mydag.py
[2024-07-01T23:27:54.897+0000] {logging_mixin.py:188} INFO - postgress link postgresql://postgres:12345@192.168.176.1:5432/postgres
[2024-07-01T23:27:54.980+0000] {logging_mixin.py:188} INFO - [2024-07-01T23:27:54.962+0000] {dagbag.py:348} ERROR - Failed to import: /opt/airflow/dags/mydag.py
Traceback (most recent call last):
  File "/home/airflow/.local/lib/python3.8/site-packages/airflow/models/dagbag.py", line 344, in parse
    loader.exec_module(new_module)
  File "<frozen importlib._bootstrap_external>", line 843, in exec_module
  File "<frozen importlib._bootstrap>", line 219, in _call_with_frames_removed
  File "/opt/airflow/dags/mydag.py", line 28, in <module>
    python_callable=data_etl.run(),
  File "/opt/airflow/dags/Scripts/data_etl.py", line 61, in run
    with WarehouseConnection(get_warehouse_creds()).managed_cursor() as curr:
  File "/usr/local/lib/python3.8/contextlib.py", line 113, in __enter__
    return next(self.gen)
  File "/opt/airflow/dags/Scripts/db.py", line 26, in managed_cursor
    self.conn = psycopg2.connect(self.conn_url)
  File "/home/airflow/.local/lib/python3.8/site-packages/psycopg2/__init__.py", line 122, in connect
    conn = _connect(dsn, connection_factory=connection_factory, **kwasync)
psycopg2.OperationalError: connection to server at "192.168.176.1", port 5432 failed: FATAL:  no pg_hba.conf entry for host "192.168.176.1", user "postgres", database "postgres", no encryption
[2024-07-01T23:27:54.983+0000] {processor.py:842} WARNING - No viable dags retrieved from /opt/airflow/dags/mydag.py
[2024-07-01T23:27:55.024+0000] {processor.py:183} INFO - Processing /opt/airflow/dags/mydag.py took 0.737 seconds
[2024-07-01T23:28:25.333+0000] {processor.py:161} INFO - Started process (PID=2616) to work on /opt/airflow/dags/mydag.py
[2024-07-01T23:28:25.335+0000] {processor.py:830} INFO - Processing file /opt/airflow/dags/mydag.py for tasks to queue
[2024-07-01T23:28:25.337+0000] {logging_mixin.py:188} INFO - [2024-07-01T23:28:25.336+0000] {dagbag.py:538} INFO - Filling up the DagBag from /opt/airflow/dags/mydag.py
[2024-07-01T23:28:25.940+0000] {logging_mixin.py:188} INFO - postgress link postgresql://postgres:12345@192.168.176.1:5432/postgres
[2024-07-01T23:28:26.031+0000] {logging_mixin.py:188} INFO - [2024-07-01T23:28:26.009+0000] {dagbag.py:348} ERROR - Failed to import: /opt/airflow/dags/mydag.py
Traceback (most recent call last):
  File "/home/airflow/.local/lib/python3.8/site-packages/airflow/models/dagbag.py", line 344, in parse
    loader.exec_module(new_module)
  File "<frozen importlib._bootstrap_external>", line 843, in exec_module
  File "<frozen importlib._bootstrap>", line 219, in _call_with_frames_removed
  File "/opt/airflow/dags/mydag.py", line 28, in <module>
    python_callable=data_etl.run(),
  File "/opt/airflow/dags/Scripts/data_etl.py", line 61, in run
    with WarehouseConnection(get_warehouse_creds()).managed_cursor() as curr:
  File "/usr/local/lib/python3.8/contextlib.py", line 113, in __enter__
    return next(self.gen)
  File "/opt/airflow/dags/Scripts/db.py", line 26, in managed_cursor
    self.conn = psycopg2.connect(self.conn_url)
  File "/home/airflow/.local/lib/python3.8/site-packages/psycopg2/__init__.py", line 122, in connect
    conn = _connect(dsn, connection_factory=connection_factory, **kwasync)
psycopg2.OperationalError: connection to server at "192.168.176.1", port 5432 failed: FATAL:  no pg_hba.conf entry for host "192.168.176.1", user "postgres", database "postgres", no encryption
[2024-07-01T23:28:26.034+0000] {processor.py:842} WARNING - No viable dags retrieved from /opt/airflow/dags/mydag.py
[2024-07-01T23:28:26.109+0000] {processor.py:183} INFO - Processing /opt/airflow/dags/mydag.py took 0.782 seconds
